Workbook

Sheet README
A1: Workbook guide
A3: How to use
A4: • Start on the Dashboard tab for high-level KPIs and charts.
A5: • Use the navigation links on the Dashboard (and the 'Home' link on each sheet) to jump around.
A6: • The Detail tab contains all 867 line items from Project_Detail.csv (filterable).
A7: • Summary tabs (Packages/CBS/Methods) roll up Detail using Excel formulas (SUMIFS/COUNTIFS).
A8: • Assumptions and Risks tabs contain the consolidated registers from the markdown files.
A9: • Inputs tab contains mappings (Package → Category) and contingency rates by CBS bucket.
A12: Notes
A13: Contingency in BOE has minor internal inconsistencies (Executive Summary vs bucket table). This workbook uses the BOE §7.2 bucket rates for calculations and shows the delta vs the BOE stated total.
A15: Data sources (local files)
A16: • Project_Detail.csv
... A21: Go to Dashboard

Sheet Dashboard
A1: Canola Oil Transload Facility — Estimate Dashboard
A2: Data snapshot: 2026-01-29 (from source files)
A4: Navigate: | C4: Base estimate (calc.) | F4: Contingency (calc.) | I4: Total estimate (calc.)
A5: Package roll-up | C5: =Summary_CBS!B12 | F5: =Summary_CBS!D12 | I5: =Summary_CBS!E12
A6: CBS roll-up
A7: Pricing methods
A8: All line items (867)
A9: Assumptions (groups) | C9: BOE stated total | F9: BOE stated contingency | I9: Delta (calc - BOE)
A10: Assumptions (items) | C10: 117100000 | F10: 24700000 | I10: =I5-C10
A11: Risks (groups)
A12: Risks (items)
A13: BOE reference
A14: Inputs / lookups | C14: # Packages | F14: # Deliverables | I14: # Line items
A15: Read me | C15: 36 | F15: 202 | I15: 867
C19: Assumptions (groups) | F19: Assumptions (raw) | I19: Risks (groups)
C20: 311 | F20: 588 | I20: 120
C24: Risks (raw) | F24: Pricing date | I24: Estimate class
C25: 297 | F25: January 2026 | I25: Class 5 (Order of Magnitude)
A30: Charts
A32: Package | B32: Total | C32: Category
A33: PKG-13 | B33: =SUMIFS(Detail!$U$2:$U$868,Detail!$F$2:$F$868,$A33) | C33: =VLOOKUP($A33,Inputs!$D$6:$E$41,2,FALSE)
A34: PKG-08 | B34: =SUMIFS(Detail!$U$2:$U$868,Detail!$F$2:$F$868,$A34) | C34: =VLOOKUP($A34,Inputs!$D$6:$E$41,2,FALSE)
A35: PKG-14 | B35: =SUMIFS(Detail!$U$2:$U$868,Detail!$F$2:$F$868,$A35) | C35: =VLOOKUP($A35,Inputs!$D$6:$E$41,2,FALSE)
A36: PKG-30 | B36: =SUMIFS(Detail!$U$2:$U$868,Detail!$F$2:$F$868,$A36) | C36: =VLOOKUP($A36,Inputs!$D$6:$E$41,2,FALSE)
A37: PKG-04 | B37: =SUMIFS(Detail!$U$2:$U$868,Detail!$F$2:$F$868,$A37) | C37: =VLOOKUP($A37,Inputs!$D$6:$E$41,2,FALSE)
A38: PKG-10 | B38: =SUMIFS(Detail!$U$2:$U$868,Detail!$F$2:$F$868,$A38) | C38: =VLOOKUP($A38,Inputs!$D$6:$E$41,2,FALSE)
A39: PKG-17 | B39: =SUMIFS(Detail!$U$2:$U$868,Detail!$F$2:$F$868,$A39) | C39: =VLOOKUP($A39,Inputs!$D$6:$E$41,2,FALSE)
A40: PKG-02 | B40: =SUMIFS(Detail!$U$2:$U$868,Detail!$F$2:$F$868,$A40) | C40: =VLOOKUP($A40,Inputs!$D$6:$E$41,2,FALSE)
A41: PKG-16 | B41: =SUMIFS(Detail!$U$2:$U$868,Detail!$F$2:$F$868,$A41) | C41: =VLOOKUP($A41,Inputs!$D$6:$E$41,2,FALSE)
A42: PKG-26 | B42: =SUMIFS(Detail!$U$2:$U$868,Detail!$F$2:$F$868,$A42) | C42: =VLOOKUP($A42,Inputs!$D$6:$E$41,2,FALSE)
A45: Category | B45: Base
A46: Site & Civil | B46: =SUMIFS(Detail!$L$2:$L$868,Detail!$R$2:$R$868,$A46)
A47: Structural | B47: =SUMIFS(Detail!$L$2:$L$868,Detail!$R$2:$R$868,$A47)
A48: Mechanical | B48: =SUMIFS(Detail!$L$2:$L$868,Detail!$R$2:$R$868,$A48)
A49: Electrical & I&C | B49: =SUMIFS(Detail!$L$2:$L$868,Detail!$R$2:$R$868,$A49)
A50: Buildings & Protection | B50: =SUMIFS(Detail!$L$2:$L$868,Detail!$R$2:$R$868,$A50)
A51: Project Execution | B51: =SUMIFS(Detail!$L$2:$L$868,Detail!$R$2:$R$868,$A51)
A56: Risk category | B56: Groups
A57: UNCATEGORIZED | B57: 46
A58: RSK-SCOPE | B58: 27
...

Sheet Summary_Packages
A1: Package summary (computed from Detail) | J1: Home
A3: Package | B3: Description | C3: PackageCategory | D3: Confidence | E3: Base | F3: Contingency | G3: Total | H3: LineItems
A4: PKG-00 | B4: Site Establishment | C4: Site & Civil | D4: LOW | E4: =SUMIFS(Detail!$L$2:$L$868,Detail!$F$2:$F$868,$A4) | F4: =SUMIFS(Detail!$T$2:$T$868,Detail!$F$2:$F$868,$A4) | G4: =$E4+$F4 | H4: =COUNTIF(Detail!$F$2:$F$868,$A4)
A5: PKG-01 | B5: Demolition & Removals | C5: Site & Civil | D5: LOW | E5: =SUMIFS(Detail!$L$2:$L$868,Detail!$F$2:$F$868,$A5) | F5: =SUMIFS(Detail!$T$2:$T$868,Detail!$F$2:$F$868,$A5) | G5: =$E5+$F5 | H5: =COUNTIF(Detail!$F$2:$F$868,$A5)
A6: PKG-02 | B6: Earthworks & Ground Improvement | C6: Site & Civil | D6: LOW | E6: =SUMIFS(Detail!$L$2:$L$868,Detail!$F$2:$F$868,$A6) | F6: =SUMIFS(Detail!$T$2:$T$868,Detail!$F$2:$F$868,$A6) | G6: =$E6+$F6 | H6: =COUNTIF(Detail!$F$2:$F$868,$A6)
A7: PKG-03 | B7: Underground Utilities & Drainage | C7: Site & Civil | D7: LOW | E7: =SUMIFS(Detail!$L$2:$L$868,Detail!$F$2:$F$868,$A7) | F7: =SUMIFS(Detail!$T$2:$T$868,Detail!$F$2:$F$868,$A7) | G7: =$E7+$F7 | H7: =COUNTIF(Detail!$F$2:$F$868,$A7)
A8: PKG-04 | B8: Pavement & Surfacing | C8: Site & Civil | D8: LOW | E8: =SUMIFS(Detail!$L$2:$L$868,Detail!$F$2:$F$868,$A8) | F8: =SUMIFS(Detail!$T$2:$T$868,Detail!$F$2:$F$868,$A8) | G8: =$E8+$F8 | H8: =COUNTIF(Detail!$F$2:$F$868,$A8)
A9: PKG-05 | B9: Concrete Structures | C9: Structural | D9: LOW | E9: =SUMIFS(Detail!$L$2:$L$868,Detail!$F$2:$F$868,$A9) | F9: =SUMIFS(Detail!$T$2:$T$868,Detail!$F$2:$F$868,$A9) | G9: =$E9+$F9 | H9: =COUNTIF(Detail!$F$2:$F$868,$A9)
A10: PKG-06 | B10: Structural Steelwork | C10: Structural | D10: LOW | E10: =SUMIFS(Detail!$L$2:$L$868,Detail!$F$2:$F$868,$A10) | F10: =SUMIFS(Detail!$T$2:$T$868,Detail!$F$2:$F$868,$A10) | G10: =$E10+$F10 | H10: =COUNTIF(Detail!$F$2:$F$868,$A10)
A11: PKG-07 | B11: Rail Works | C11: Structural | D11: LOW | E11: =SUMIFS(Detail!$L$2:$L$868,Detail!$F$2:$F$868,$A11) | F11: =SUMIFS(Detail!$T$2:$T$868,Detail!$F$2:$F$868,$A11) | G11: =$E11+$F11 | H11: =COUNTIF(Detail!$F$2:$F$868,$A11)
A12: PKG-08 | B12: Marine Structures | C12: Structural | D12: LOW | E12: =SUMIFS(Detail!$L$2:$L$868,Detail!$F$2:$F$868,$A12) | F12: =SUMIFS(Detail!$T$2:$T$868,Detail!$F$2:$F$868,$A12) | G12: =$E12+$F12 | H12: =COUNTIF(Detail!$F$2:$F$868,$A12)
A13: PKG-09 | B13: Marine Outfitting | C13: Structural | D13: LOW | E13: =SUMIFS(Detail!$L$2:$L$868,Detail!$F$2:$F$868,$A13) | F13: =SUMIFS(Detail!$T$2:$T$868,Detail!$F$2:$F$868,$A13) | G13: =$E13+$F13 | H13: =COUNTIF(Detail!$F$2:$F$868,$A13)
A14: PKG-10 | B14: Railcar Unloading System | C14: Mechanical | D14: LOW | E14: =SUMIFS(Detail!$L$2:$L$868,Detail!$F$2:$F$868,$A14) | F14: =SUMIFS(Detail!$T$2:$T$868,Detail!$F$2:$F$868,$A14) | G14: =$E14+$F14 | H14: =COUNTIF(Detail!$F$2:$F$868,$A14)
A15: PKG-11 | B15: Marine Loading System | C15: Mechanical | D15: LOW | E15: =SUMIFS(Detail!$L$2:$L$868,Detail!$F$2:$F$868,$A15) | F15: =SUMIFS(Detail!$T$2:$T$868,Detail!$F$2:$F$868,$A15) | G15: =$E15+$F15 | H15: =COUNTIF(Detail!$F$2:$F$868,$A15)
... A39: PKG-35 | B39: Training & Handover | C39: Project Execution | D39: LOW | E39: =SUMIFS(Detail!$L$2:$L$868,Detail!$F$2:$F$868,$A39) | F39: =SUMIFS(Detail!$T$2:$T$868,Detail!$F$2:$F$868,$A39) | G39: =$E39+$F39 | H39: =COUNTIF(Detail!$F$2:$F$868,$A39)

Sheet Summary_CBS
A1: CBS summary (computed from Detail) | H1: Home
A3: CBS | B3: Base | C3: Rate | D3: Contingency | E3: Total | F3: Share_of_Total
A4: MAT | B4: =SUMIFS(Detail!$L$2:$L$868,Detail!$E$2:$E$868,$A4) | C4: =VLOOKUP($A4,Inputs!$A$6:$B$13,2,FALSE)*Inputs!$B$2 | D4: =$B4*$C4 | E4: =$B4+$D4 | F4: =$E4/SUM($E$4:$E$11)
A5: CD | B5: =SUMIFS(Detail!$L$2:$L$868,Detail!$E$2:$E$868,$A5) | C5: =VLOOKUP($A5,Inputs!$A$6:$B$13,2,FALSE)*Inputs!$B$2 | D5: =$B5*$C5 | E5: =$B5+$D5 | F5: =$E5/SUM($E$4:$E$11)
A6: E | B6: =SUMIFS(Detail!$L$2:$L$868,Detail!$E$2:$E$868,$A6) | C6: =VLOOKUP($A6,Inputs!$A$6:$B$13,2,FALSE)*Inputs!$B$2 | D6: =$B6*$C6 | E6: =$B6+$D6 | F6: =$E6/SUM($E$4:$E$11)
A7: PM | B7: =SUMIFS(Detail!$L$2:$L$868,Detail!$E$2:$E$868,$A7) | C7: =VLOOKUP($A7,Inputs!$A$6:$B$13,2,FALSE)*Inputs!$B$2 | D7: =$B7*$C7 | E7: =$B7+$D7 | F7: =$E7/SUM($E$4:$E$11)
A8: CI | B8: =SUMIFS(Detail!$L$2:$L$868,Detail!$E$2:$E$868,$A8) | C8: =VLOOKUP($A8,Inputs!$A$6:$B$13,2,FALSE)*Inputs!$B$2 | D8: =$B8*$C8 | E8: =$B8+$D8 | F8: =$E8/SUM($E$4:$E$11)
A9: COM | B9: =SUMIFS(Detail!$L$2:$L$868,Detail!$E$2:$E$868,$A9) | C9: =VLOOKUP($A9,Inputs!$A$6:$B$13,2,FALSE)*Inputs!$B$2 | D9: =$B9*$C9 | E9: =$B9+$D9 | F9: =$E9/SUM($E$4:$E$11)
A10: P | B10: =SUMIFS(Detail!$L$2:$L$868,Detail!$E$2:$E$868,$A10) | C10: =VLOOKUP($A10,Inputs!$A$6:$B$13,2,FALSE)*Inputs!$B$2 | D10: =$B10*$C10 | E10: =$B10+$D10 | F10: =$E10/SUM($E$4:$E$11)
A11: FRT | B11: =SUMIFS(Detail!$L$2:$L$868,Detail!$E$2:$E$868,$A11) | C11: =VLOOKUP($A11,Inputs!$A$6:$B$13,2,FALSE)*Inputs!$B$2 | D11: =$B11*$C11 | E11: =$B11+$D11 | F11: =$E11/SUM($E$4:$E$11)
A12: TOTAL | B12: =SUM(B4:B11) | D12: =SUM(D4:D11) | E12: =SUM(E4:E11) | F12: 1

Sheet Summary_Methods
A1: Pricing method summary (computed from Detail) | G1: Home
A3: Method | B3: LineItems | C3: Base | D3: Share_of_Base
A4: ALLOWANCE | B4: =COUNTIF(Detail!$N$2:$N$868,$A4) | C4: =SUMIFS(Detail!$L$2:$L$868,Detail!$N$2:$N$868,$A4) | D4: =$C4/SUM($C$4:$C$7)
A5: CAD | B5: =COUNTIF(Detail!$N$2:$N$868,$A5) | C5: =SUMIFS(Detail!$L$2:$L$868,Detail!$N$2:$N$868,$A5) | D5: =$C5/SUM($C$4:$C$7)
A6: PARAMETRIC | B6: =COUNTIF(Detail!$N$2:$N$868,$A6) | C6: =SUMIFS(Detail!$L$2:$L$868,Detail!$N$2:$N$868,$A6) | D6: =$C6/SUM($C$4:$C$7)
A7: RATE_TABLE | B7: =COUNTIF(Detail!$N$2:$N$868,$A7) | C7: =SUMIFS(Detail!$L$2:$L$868,Detail!$N$2:$N$868,$A7) | D7: =$C7/SUM($C$4:$C$7)

Sheet Assumptions_Groups
A1: Assumptions — consolidated groups | I1: Home
A3: CategoryCode | B3: Category | C3: GroupID | D3: GroupTitle | E3: Theme | F3: PackagesCount | G3: Packages | H3: ItemsCount
A4: ASM-ENG | B4: Engineering Effort | C4: ASM-ENG-001 | D4: Design Calculations Effort | E4: Design Calculations Effort | F4: 8 | G4: PKG-05, PKG-06, PKG-08, PKG-10, PKG-11, PKG-17, PKG-20, PKG-21 | H4: 8
A5: ASM-ENG | B5: Engineering Effort | C5: ASM-ENG-002 | D5: Calculations | F5: 1 | G5: PKG-13 | H5: 1
A6: ASM-ENG | B6: Engineering Effort | C6: ASM-ENG-003 | D6: Design Codes and Standards | F6: 1 | G6: PKG-23 | H6: 1
A7: ASM-ENG | B7: Engineering Effort | C7: ASM-ENG-004 | D7: Drawings | F7: 1 | G7: PKG-13 | H7: 1
A8: ASM-ENG | B8: Engineering Effort | C8: ASM-ENG-005 | D8: Engineering Design Effort (6 Deliverables) | F8: 1 | G8: PKG-22 | H8: 1
A9: ASM-ENG | B9: Engineering Effort | C9: ASM-ENG-006 | D9: Engineering Drawing Effort | F9: 1 | G9: PKG-20 | H9: 1
A10: ASM-ENG | B10: Engineering Effort | C10: ASM-ENG-007 | D10: Engineering design at approximately 11% of construction value | F10: 1 | G10: PKG-21 | H10: 1
A11: ASM-ENG | B11: Engineering Effort | C11: ASM-ENG-008 | D11: Engineering effort estimated at **3,400 hours** across 5 deliverables | F11: 1 | G11: PKG-16 | H11: 1
A12: ASM-ENG | B12: Engineering Effort | C12: ASM-ENG-009 | D12: Lighting poles designed for NBCC 2020 seismic and wind loads for Surrey, BC loca... | F12: 1 | G12: PKG-18 | H12: 1
A13: ASM-ENG | B13: Engineering Effort | C13: ASM-ENG-010 | D13: Shop Drawings and Submittals | F13: 1 | G13: PKG-22 | H13: 1
A14: ASM-ENG | B14: Engineering Effort | C14: ASM-ENG-011 | D14: Specifications | F14: 1 | G14: PKG-13 | H14: 1
A15: ASM-ENG | B15: Engineering Effort | C15: ASM-ENG-012 | D15: Three HMI workstations: 2 operator stations + 1 engineering station | F15: 1 | G15: PKG-19 | H15: 1
A16: ASM-INTF | B16: Interface & Coordination | C16: ASM-INTF-013 | D16: Interface Dependencies | E16: Interface Dependencies | F16: 1 | G16: PKG-22 | H16: 4
A17: ASM-INTF | B17: Interface & Coordination | C17: ASM-INTF-014 | D17: PKG-27 A-2701 | F17: 4 | G17: PKG-27, PKG-28, PKG-29, PKG-30 | H17: 73
A18: ASM-INTF | B18: Interface & Coordination | C18: ASM-INTF-015 | D18: PKG-24 assumption A-001 - see source | F18: 2 | G18: PKG-24, PKG-25 | H18: 41
A19: ASM-INTF | B19: Interface & Coordination | C19: ASM-INTF-016 | D19: PKG-26 assumption A-2601 | F19: 1 | G19: PKG-26 | H19: 25
A20: ASM-INTF | B20: Interface & Coordination | C20: ASM-INTF-017 | D20: 40-60 HMI graphics screens for operator interface | F20: 1 | G20: PKG-19 | H20: 1
A21: ASM-INTF | B21: Interface & Coordination | C21: ASM-INTF-018 | D21: Control system equipment installed in MCC building per PKG-21/22 | F21: 1 | G21: PKG-19 | H21: 1
A22: ASM-INTF | B22: Interface & Coordination | C22: ASM-INTF-019 | D22: Coordination Meeting Records — DEL-34.01 | F22: 1 | G22: PKG-34 | H22: 1
A23: ASM-INTF | B23: Interface & Coordination | C23: ASM-INTF-020 | D23: Interface Agreements — DEL-34.02 | F23: 1 | G23: PKG-34 | H23: 1
A24: ASM-INTF | B24: Interface & Coordination | C24: ASM-INTF-021 | D24: Marine Coordination Records — DEL-34.03 | F24: 1 | G24: PKG-34 | H24: 1
A25: ASM-INTF | B25: Interface & Coordination | C25: ASM-INTF-022 | D25: Marine loading system (PKG-11) requires **~25 valves** (loading arm isolation, f... | F25: 1 | G25: PKG-16 | H25: 1
A26: ASM-INTF | B26: Interface & Coordination | C26: ASM-INTF-023 | D26: Product transfer and metering (PKG-12) requires **~30 valves** | F26: 1 | G26: PKG-16 | H26: 1
A27: ASM-INTF | B27: Interface & Coordination | C27: ASM-INTF-024 | D27: Site Access and Temporary Works (PKG-06 Allocation) | F27: 1 | G27: PKG-06 | H27: 1
A28: ASM-INTF | B28: Interface & Coordination | C28: ASM-INTF-025 | D28: Terminal Operations Coordination | F28: 1 | G28: PKG-23 | H28: 1
A29: ASM-LABOR | B29: Labor & Installation | C29: ASM-LABOR-026 | D29: Installation Labor Rates | E29: Installation Labor Rates | F29: 5 | G29: PKG-11, PKG-14, PKG-15, PKG-16, PKG-21 | H29: 11
A30: ASM-LABOR | B30: Labor & Installation | C30: ASM-LABOR-027 | D30: Actuator hookup (pneumatic/electrical) adds **2-4 hours per actuated valve** | F30: 1 | G30: PKG-16 | H30: 1
A31: ASM-LABOR | B31: Labor & Installation | C31: ASM-LABOR-028 | D31: Cable Tray and Conduit Installation Scope | F31: 1 | G31: PKG-17 | H31: 1
A32: ASM-LABOR | B32: Labor & Installation | C32: ASM-LABOR-029 | D32: Construction Labor Productivity | F32: 1 | G32: PKG-23 | H32: 1
A33: ASM-LABOR | B33: Labor & Installation | C33: ASM-LABOR-030 | D33: Construction Labor Rates (BC Lower Mainland) | F33: 1 | G33: PKG-22 | H33: 1
A34: ASM-LABOR | B34: Labor & Installation | C34: ASM-LABOR-031 | D34: Control valve calibration and loop check (30 valves) estimated at **4 hours per ... | F34: 1 | G34: PKG-16 | H34: 1
A35: ASM-LABOR | B35: Labor & Installation | C35: ASM-LABOR-032 | D35: Crane and Equipment for Steel Erection | F35: 1 | G35: PKG-06 | H35: 1
A36: ASM-LABOR | B36: Labor & Installation | C36: ASM-LABOR-033 | D36: Distribution Panel Installation Scope | F36: 1 | G36: PKG-17 | H36: 1
A37: ASM-LABOR | B37: Labor & Installation | C37: ASM-LABOR-034 | D37: Engineering Labor Hours | F37: 1 | G37: PKG-23 | H37: 1
A38: ASM-LABOR | B38: Labor & Installation | C38: ASM-LABOR-035 | D38: Fire Water Loop Installation Productivity | F38: 1 | G38: PKG-23 | H38: 1
A39: ASM-LABOR | B39: Labor & Installation | C39: ASM-LABOR-036 | D39: Grating Supply and Installation | F39: 1 | G39: PKG-06 | H39: 1
A40: ASM-LABOR | B40: Labor & Installation | C40: ASM-LABOR-037 | D40: Grounding System Installation Scope | F40: 1 | G40: PKG-17 | H40: 1
A41: ASM-LABOR | B41: Labor & Installation | C41: ASM-LABOR-038 | D41: Handrail Supply and Installation | F41: 1 | G41: PKG-06 | H41: 1
...

Sheet Assumptions_Items
A1: Assumptions — source items | H1: Home
A3: CategoryCode | B3: Category | C3: GroupID | D3: GroupTitle | E3: Package | F3: AssumptionID | G3: Description
A4: ASM-ENG | B4: Engineering Effort | C4: ASM-ENG-001 | D4: Design Calculations Effort | E4: PKG-05 | F4: A-003 | G4: Concrete structures design calculations (foundation calcs,..
A5: ASM-ENG | B5: Engineering Effort | C5: ASM-ENG-001 | D5: Design Calculations Effort | E5: PKG-06 | F5: A-003 | G5: Structural Steel Design Calculations Effort
A6: ASM-ENG | B6: Engineering Effort | C6: ASM-ENG-001 | D6: Design Calculations Effort | E6: PKG-08 | F6: A-803 | G6: DEL-08.03 Design Calculations Allowance
A7: ASM-ENG | B7: Engineering Effort | C7: ASM-ENG-001 | D7: Design Calculations Effort | E7: PKG-10 | F7: A-008 | G7: DEL-10.03 Design Calculations engineering effort priced at..
A8: ASM-ENG | B8: Engineering Effort | C8: ASM-ENG-001 | D8: Design Calculations Effort | E8: PKG-11 | F8: A-009 | G8: Design calculations require ~80 hours at $250/hr (senior p..
A9: ASM-ENG | B9: Engineering Effort | C9: ASM-ENG-001 | D9: Design Calculations Effort | E9: PKG-17 | F9: A-1703 | G9: Electrical Power Design Calculations Allowance
A10: ASM-ENG | B10: Engineering Effort | C10: ASM-ENG-001 | D10: Design Calculations Effort | E10: PKG-20 | F10: A-013 | G10: Design Calculation Effort
A11: ASM-ENG | B11: Engineering Effort | C11: ASM-ENG-001 | D11: Design Calculations Effort | E11: PKG-21 | F11: A-005 | G11: Structural/foundation calculations at $45,000 allowance
A12: ASM-ENG | B12: Engineering Effort | C12: ASM-ENG-002 | D12: Calculations | E12: PKG-13 | F12: A-013 | G12: Calculations
A13: ASM-ENG | B13: Engineering Effort | C13: ASM-ENG-003 | D13: Design Codes and Standards | E13: PKG-23 | F13: A-022 | G13: Design Codes and Standards
A14: ASM-ENG | B14: Engineering Effort | C14: ASM-ENG-004 | D14: Drawings | E14: PKG-13 | F14: A-011 | G14: Drawings
... A591: UNCATEGORIZED | B591: Uncategorized | C591: UNCATEGORIZED-311 | D591: Weld Inspection and NDT | E591: PKG-06 | F591: A-015 | G591: Weld Inspection and NDT

Sheet Risks_Groups
A1: Risks — consolidated groups | I1: Home
A3: CategoryCode | B3: Category | C3: GroupID | D3: GroupTitle | E3: Theme | F3: PackagesCount | G3: Packages | H3: ItemsCount
A4: RSK-ENV | B4: Environmental Risk | C4: RSK-ENV-001 | D4: Weather/Environmental Risk | E4: Weather/Environmental Risk | F4: 9 | G4: PKG-01, PKG-08, PKG-11, PKG-13, PKG-14, PKG-16, PKG-20, PKG-21, PKG-23 | H4: 10
A5: RSK-ENV | B5: Environmental Risk | C5: RSK-ENV-002 | D5: Marine Logistics Constraints | F5: 1 | G5: PKG-08 | H5: 1
A6: RSK-ESC | B6: Escalation Risk | C6: RSK-ESC-003 | D6: Cost Escalation Exposure | E6: Cost Escalation Exposure | F6: 11 | G6: PKG-00, PKG-05, PKG-15, PKG-16, PKG-22, PKG-23, PKG-31, PKG-32, PKG-33, PKG-34, PKG-35 | H6: 14
A7: RSK-INTF | B7: Interface Risk | C7: RSK-INTF-004 | D7: Interface & Coordination Risk | E7: Interface & Coordination Risk | F7: 9 | G7: PKG-00, PKG-05, PKG-10, PKG-11, PKG-14, PKG-16, PKG-22, PKG-32, PKG-34 | H7: 16
A8: RSK-INTF | B8: Interface Risk | C8: RSK-INTF-005 | D8: PKG-27 R-2701 | F8: 4 | G8: PKG-27, PKG-28, PKG-29, PKG-30 | H8: 38
A9: RSK-INTF | B9: Interface Risk | C9: RSK-INTF-006 | D9: PKG-24 risk R-001 - see source | F9: 2 | G9: PKG-24, PKG-25 | H9: 18
A10: RSK-INTF | B10: Interface Risk | C10: RSK-INTF-007 | D10: PKG-26 risk R-2601 | F10: 1 | G10: PKG-26 | H10: 8
A11: RSK-INTF | B11: Interface Risk | C11: RSK-INTF-008 | D11: Control Room Integration | F11: 1 | G11: PKG-19 | H11: 1
A12: RSK-INTF | B12: Interface Risk | C12: RSK-INTF-009 | D12: Coordination and Interface Delays | F12: 1 | G12: PKG-15 | H12: 1
A13: RSK-INTF | B13: Interface Risk | C13: RSK-INTF-010 | D13: Emergency Response Plan Integration Complexity | F13: 1 | G13: PKG-33 | H13: 1
A14: RSK-INTF | B14: Interface Risk | C14: RSK-INTF-011 | D14: Integration with Control System | F14: 1 | G14: PKG-15 | H14: 1
A15: RSK-INTF | B15: Interface Risk | C15: RSK-INTF-012 | D15: Integration with Existing Terminal Systems | F15: 1 | G15: PKG-19 | H15: 1
A16: RSK-INTF | B16: Interface Risk | C16: RSK-INTF-013 | D16: Interface - Marine Access | F16: 1 | G16: PKG-11 | H16: 1
A17: RSK-INTF | B17: Interface Risk | C17: RSK-INTF-014 | D17: Interface with Other Packages (HSE Dependencies) | F17: 1 | G17: PKG-33 | H17: 1
A18: RSK-INTF | B18: Interface Risk | C18: RSK-INTF-015 | D18: Loop Testing Coordination | F18: 1 | G18: PKG-20 | H18: 1
A19: RSK-INTF | B19: Interface Risk | C19: RSK-INTF-016 | D19: Marine Coordination Complexity | F19: 1 | G19: PKG-34 | H19: 1
... A21: RSK-INTF | B21: Interface Risk | C21: RSK-INTF-018 | D21: Site Access and Operational Interface Risk | F21: 1 | G21: PKG-16 | H21: 1
A22: RSK-PRICE | B22: Price Uncertainty | C22: RSK-PRICE-019 | D22: No Vendor Pricing/Quotes Available | E22: No Vendor Pricing/Quotes Available | F22: 9 | G22: PKG-00, PKG-01, PKG-05, PKG-10, PKG-11, PKG-14, PKG-15, PKG-16, PKG-34 | H22: 9
A23: RSK-PRICE | B23: Price Uncertainty | C23: RSK-PRICE-020 | D23: Control System Vendor Selection | F23: 1 | G23: PKG-19 | H23: 1
A24: RSK-PRICE | B24: Price Uncertainty | C24: RSK-PRICE-021 | D24: Equipment - Loading Arm Pricing | F24: 1 | G24: PKG-11 | H24: 1
A25: RSK-PRICE | B25: Price Uncertainty | C25: RSK-PRICE-022 | D25: Marine Contractor Availability and Pricing Volatility | F25: 1 | G25: PKG-08 | H25: 1
A26: RSK-PRICE | B26: Price Uncertainty | C26: RSK-PRICE-023 | D26: Steel price volatility | F26: 1 | G26: PKG-13 | H26: 1
A27: RSK-PRICE | B27: Price Uncertainty | C27: RSK-PRICE-024 | D27: Vendor FAT Location | F27: 1 | G27: PKG-19 | H27: 1
A28: RSK-PRICE | B28: Price Uncertainty | C28: RSK-PRICE-025 | D28: Vendor Quote Unavailability | F28: 1 | G28: PKG-22 | H28: 1
A29: RSK-PROD | B29: Productivity Risk | C29: RSK-PROD-026 | D29: Labor Availability & Productivity | E29: Labor Availability & Productivity | F29: 6 | G29: PKG-05, PKG-10, PKG-15, PKG-16, PKG-21, PKG-22 | H29: 7
A30: RSK-PROD | B30: Productivity Risk | C30: RSK-PROD-027 | D30: Site Access During Operations | F30: 1 | G30: PKG-20 | H30: 1
A31: RSK-QTY | B31: Quantity Risk | C31: RSK-QTY-028 | D31: Quantity Uncertainty | E31: Quantity Uncertainty | F31: 5 | G31: PKG-05, PKG-15, PKG-16, PKG-20, PKG-33 | H31: 5
A32: RSK-QTY | B32: Quantity Risk | C32: RSK-QTY-029 | D32: Actuator Sizing and Safety Factor Risk | F32: 1 | G32: PKG-16 | H32: 1
A33: RSK-QTY | B33: Quantity Risk | C33: RSK-QTY-030 | D33: Method Statement and Risk Assessment Volume | F33: 1 | G33: PKG-33 | H33: 1
A34: RSK-QUAL | B34: Quality Risk | C34: RSK-QUAL-031 | D34: Quality/Rework Risk | E34: Quality/Rework Risk | F34: 6 | G34: PKG-11, PKG-13, PKG-14, PKG-15, PKG-31, PKG-35 | H34: 6
A35: RSK-QUAL | B35: Quality Risk | C35: RSK-QUAL-032 | D35: Engineering Effort Underestimated (LOW) | F35: 1 | G35: PKG-01 | H35: 1
A36: RSK-QUAL | B36: Quality Risk | C36: RSK-QUAL-033 | D36: NDE findings | F36: 1 | G36: PKG-13 | H36: 1
A37: RSK-QUAL | B37: Quality Risk | C37: RSK-QUAL-034 | D37: Underground Utility Conflicts | F37: 1 | G37: PKG-23 | H37: 1
A38: RSK-REG | B38: Regulatory Risk | C38: RSK-REG-035 | D38: Regulatory/Permitting Risk | E38: Regulatory/Permitting Risk | F38: 9 | G38: PKG-00, PKG-08, PKG-10, PKG-11, PKG-15, PKG-21, PKG-23, PKG-32, PKG-33 | H38: 10
A39: RSK-SCHED | B39: Schedule Risk | C39: RSK-SCHED-036 | D39: Schedule/Lead Time Risk | E39: Schedule/Lead Time Risk | F39: 11 | G39: PKG-00, PKG-08, PKG-11, PKG-14, PKG-15, PKG-16, PKG-18, PKG-20, PKG-21, PKG-23, PKG-35 | H39: 11
A40: RSK-SCHED | B40: Schedule Risk | C40: RSK-SCHED-037 | D40: Construction Schedule Duration Variance | F40: 1 | G40: PKG-33 | H40: 1
A41: RSK-SCHED | B41: Schedule Risk | C41: RSK-SCHED-038 | D41: Employer Staffing Delays (LOW) | F41: 1 | G41: PKG-35 | H41: 1
A42: RSK-SCHED | B42: Schedule Risk | C42: RSK-SCHED-039 | D42: Project Duration Extension | F42: 1 | G42: PKG-34 | H42: 1
...

Sheet Risks_Items
A1: Risks — source items | I1: Home
A3: CategoryCode | B3: Category | C3: GroupID | D3: GroupTitle | E3: Package | F3: RiskID | G3: RiskTitle | H3: Severity
A4: RSK-ENV | B4: Environmental Risk | C4: RSK-ENV-001 | D4: Weather/Environmental Risk | E4: PKG-01 | F4: R-104 | G4: Marine Weather/Tide Delays (MEDIUM) | H4: MEDIUM
A5: RSK-ENV | B5: Environmental Risk | C5: RSK-ENV-001 | D5: Weather/Environmental Risk | E5: PKG-08 | F5: R-805 | G5: Environmental Design Basis More Severe Than Assumed
A6: RSK-ENV | B6: Environmental Risk | C6: RSK-ENV-001 | D6: Weather/Environmental Risk | E6: PKG-11 | F6: R-011 | G6: Environmental - Weather
A7: RSK-ENV | B7: Environmental Risk | C7: RSK-ENV-001 | D7: Weather/Environmental Risk | E7: PKG-13 | F7: R-008 | G7: Weather impacts
A8: RSK-ENV | B8: Environmental Risk | C8: RSK-ENV-001 | D8: Weather/Environmental Risk | E8: PKG-14 | F8: R-016 | G8: Environmental - Material Storage
A9: RSK-ENV | B9: Environmental Risk | C9: RSK-ENV-001 | D9: Weather/Environmental Risk | E9: PKG-16 | F9: R-1620 | G9: Winter Construction Productivity Impact
A10: RSK-ENV | B10: Environmental Risk | C10: RSK-ENV-001 | D10: Weather/Environmental Risk | E10: PKG-20 | F10: R-006 | G10: Marine Environment Corrosion
A11: RSK-ENV | B11: Environmental Risk | C11: RSK-ENV-001 | D11: Weather/Environmental Risk | E11: PKG-20 | F11: R-012 | G11: Winter Weather Impact
A12: RSK-ENV | B12: Environmental Risk | C12: RSK-ENV-001 | D12: Weather/Environmental Risk | E12: PKG-21 | F12: R-004 | G12: Marine Environment Corrosion Protection
A13: RSK-ENV | B13: Environmental Risk | C13: RSK-ENV-001 | D13: Weather/Environmental Risk | E13: PKG-23 | F13: R-010 | G13: Marine Environment Corrosion
A14: RSK-ENV | B14: Environmental Risk | C14: RSK-ENV-002 | D14: Marine Logistics Constraints | E14: PKG-08 | F14: R-802 | G14: Marine Logistics Constraints
A15: RSK-ESC | B15: Escalation Risk | C15: RSK-ESC-003 | D15: Cost Escalation Exposure | E15: PKG-00 | F15: R-008 | G15: Currency and Escalation Exposure
A16: RSK-ESC | B16: Escalation Risk | C16: RSK-ESC-003 | D16: Cost Escalation Exposure | E16: PKG-05 | F16: R-008 | G16: Escalation Exposure
... A27: RSK-ESC | B27: Escalation Risk | C27: RSK-ESC-003 | D27: Cost Escalation Exposure | E27: PKG-34 | F27: R-008 | G27: Escalation Exposure — Labor Rate Increases
A28: RSK-ESC | B28: Escalation Risk | C28: RSK-ESC-003 | D28: Cost Escalation Exposure | E28: PKG-35 | F28: R-008 | G28: Escalation Exposure (MEDIUM) | H28: MEDIUM
A29: RSK-INTF | B29: Interface Risk | C29: RSK-INTF-004 | D29: Interface & Coordination Risk | E29: PKG-00 | F29: R-004 | G29: Terminal Operational Constraints and Interface Complexity
A30: RSK-INTF | B30: Interface Risk | C30: RSK-INTF-004 | D30: Interface & Coordination Risk | E30: PKG-05 | F30: R-006 | G30: Interface Coordination Complexity
A31: RSK-INTF | B31: Interface Risk | C31: RSK-INTF-004 | D31: Interface & Coordination Risk | E31: PKG-10 | F31: R-005 | G31: Interface Coordination Risk
A32: RSK-INTF | B32: Interface Risk | C32: RSK-INTF-004 | D32: Interface & Coordination Risk | E32: PKG-10 | F32: R-010 | G32: PKG-07 Rail Track Interface Risk
A33: RSK-INTF | B33: Interface Risk | C33: RSK-INTF-004 | D33: Interface & Coordination Risk | E33: PKG-11 | F33: R-005 | G33: Interface - PKG-08
A34: RSK-INTF | B34: Interface Risk | C34: RSK-INTF-004 | D34: Interface & Coordination Risk | E34: PKG-11 | F34: R-009 | G34: Interface - PKG-19
A35: RSK-INTF | B35: Interface Risk | C35: RSK-INTF-004 | D35: Interface & Coordination Risk | E35: PKG-14 | F35: R-006 | G35: Interface - PKG-10
A36: RSK-INTF | B36: Interface Risk | C36: RSK-INTF-004 | D36: Interface & Coordination Risk | E36: PKG-14 | F36: R-007 | G36: Interface - PKG-11
A37: RSK-INTF | B37: Interface Risk | C37: RSK-INTF-004 | D37: Interface & Coordination Risk | E37: PKG-14 | F37: R-008 | G37: Interface - PKG-13
A38: RSK-INTF | B38: Interface Risk | C38: RSK-INTF-004 | D38: Interface & Coordination Risk | E38: PKG-14 | F38: R-009 | G38: Interface - PKG-15
A39: RSK-INTF | B39: Interface Risk | C39: RSK-INTF-004 | D39: Interface & Coordination Risk | E39: PKG-16 | F39: R-1608 | G39: Relief Valve Set Pressure and Protected Equipment Coordina..
A40: RSK-INTF | B40: Interface Risk | C40: RSK-INTF-004 | D40: Interface & Coordination Risk | E40: PKG-22 | F40: R-007 | G40: PKG-19 Control System Interface Scope Split
... A120: RSK-PRICE | B120: Price Uncertainty | C120: RSK-PRICE-019 | D120: No Vendor Pricing/Quotes Available | E120: PKG-00 | F120: R-001 | G120: Lack of Project-Specific Pricing Sources
A121: RSK-PRICE | B121: Price Uncertainty | C121: RSK-PRICE-019 | D121: No Vendor Pricing/Quotes Available | E121: PKG-01 | F121: R-106 | G121: No Vendor Quotes — Estimate Accuracy (MEDIUM) | H121: MEDIUM
A122: RSK-PRICE | B122: Price Uncertainty | C122: RSK-PRICE-019 | D122: No Vendor Pricing/Quotes Available | E122: PKG-05 | F122: R-001 | G122: No Vendor Pricing Available
A123: RSK-PRICE | B123: Price Uncertainty | C123: RSK-PRICE-019 | D123: No Vendor Pricing/Quotes Available | E123: PKG-10 | F123: R-001 | G123: Unloading Arm Pricing Uncertainty
A124: RSK-PRICE | B124: Price Uncertainty | C124: RSK-PRICE-019 | D124: No Vendor Pricing/Quotes Available | E124: PKG-11 | F124: R-004 | G124: Price - No Quotes
A125: RSK-PRICE | B125: Price Uncertainty | C125: RSK-PRICE-019 | D125: No Vendor Pricing/Quotes Available | E125: PKG-14 | F125: R-005 | G125: Price - No Quotes
A126: RSK-PRICE | B126: Price Uncertainty | C126: RSK-PRICE-019 | D126: No Vendor Pricing/Quotes Available | E126: PKG-15 | F126: R-002 | G126: Equipment Pricing Uncertainty
A127: RSK-PRICE | B127: Price Uncertainty | C127: RSK-PRICE-019 | D127: No Vendor Pricing/Quotes Available | E127: PKG-16 | F127: R-1606 | G127: Vendor Pricing Variability
A128: RSK-PRICE | B128: Price Uncertainty | C128: RSK-PRICE-019 | D128: No Vendor Pricing/Quotes Available | E128: PKG-34 | F128: R-004 | G128: Lack of Project-Specific Pricing Sources
A129: RSK-PRICE | B129: Price Uncertainty | C129: RSK-PRICE-020 | D129: Control System Vendor Selection | E129: PKG-19 | F129: R-001 | G129: Control System Vendor Selection
A130: RSK-PRICE | B130: Price Uncertainty | C130: RSK-PRICE-021 | D130: Equipment - Loading Arm Pricing | E130: PKG-11 | F130: R-001 | G130: Equipment - Loading Arm Pricing
...

Sheet Detail
A1: LineUID | B1: FromPackageID | C1: FromDeliverableID | D1: LineID | E1: CBS | F1: WBS_PackageID | G1: WBS_DeliverableID | H1: Description | I1: Qty | J1: Unit | K1: UnitRate | L1: Amount | M1: Currency | N1: Method | O1: SourceRef | P1: Confidence | Q1: Notes | R1: Category | S1: ContingencyRate | T1: ContingencyAmount | U1: TotalWithContingency | X1: Home
A2: PKG-00::L001 | B2: PKG-00 | C2: DEL-00.01 | D2: L001 | E2: E | F2: PKG-00 | G2: DEL-00.01 | H2: Site Establishment Design Drawing Set - CAD drafting and production (4 drawings) | I2: 1 | J2: LS | K2: 12000 | L2: 12000 | M2: CAD | N2: ALLOWANCE | O2: A-001 | P2: LOW | Q2: Allowance for drawing production without vendor quotes or rate tables | R2: =VLOOKUP($F2,Inputs!$D$6:$E$41,2,FALSE) | S2: =VLOOKUP($E2,Inputs!$A$6:$B$13,2,FALSE)*Inputs!$B$2 | T2: =$L2*$S2 | U2: =$L2+$T2
A3: PKG-00::L002 | B3: PKG-00 | C3: DEL-00.02 | D3: L002 | E3: E | F3: PKG-00 | G3: DEL-00.02 | H3: Site Establishment Technical Specification - specification writing (2 specifications) | I3: 1 | J3: LS | K3: 10000 | L3: 10000 | M3: CAD | N3: ALLOWANCE | O3: A-002 | P3: LOW | Q3: Allowance for specification writing without rate tables | R3: =VLOOKUP($F3,Inputs!$D$6:$E$41,2,FALSE) | S3: =VLOOKUP($E3,Inputs!$A$6:$B$13,2,FALSE)*Inputs!$B$2 | T3: =$L3*$S3 | U3: =$L3+$T3
A4: PKG-00::L003 | B4: PKG-00 | C4: DEL-00.03 | D4: L003 | E4: PM | F4: PKG-00 | G4: DEL-00.03 | H4: Site Establishment Procedures - procedure development (3 procedures) | I4: 1 | J4: LS | K4: 9000 | L4: 9000 | M4: CAD | N4: ALLOWANCE | O4: A-003 | P4: LOW | Q4: Allowance for PM procedure development | R4: =VLOOKUP($F4,Inputs!$D$6:$E$41,2,FALSE) | S4: =VLOOKUP($E4,Inputs!$A$6:$B$13,2,FALSE)*Inputs!$B$2 | T4: =$L4*$S4 | U4: =$L4+$T4
A5: PKG-00::L004 | B5: PKG-00 | C5: DEL-00.04 | D5: L004 | E5: PM | F5: PKG-00 | G5: DEL-00.04 | H5: Contractor's Equipment Schedule - project controls documentation (2 documents) | I5: 1 | J5: LS | K5: 5000 | L5: 5000 | M5: CAD | N5: ALLOWANCE | O5: A-004 | P5: LOW | Q5: Allowance for equipment schedule preparation | R5: =VLOOKUP($F5,Inputs!$D$6:$E$41,2,FALSE) | S5: =VLOOKUP($E5,Inputs!$A$6:$B$13,2,FALSE)*Inputs!$B$2 | T5: =$L5*$S5 | U5: =$L5+$T5
A6: PKG-00::L005 | B6: PKG-00 | C6: DEL-00.05 | D6: L005 | E6: PM | F6: PKG-00 | G6: DEL-00.05 | H6: Road Access & Security Planning - access/security process documentation (3 plans) | I6: 1 | J6: LS | K6: 8000 | L6: 8000 | M6: CAD | N6: ALLOWANCE | O6: A-005 | P6: LOW | Q6: Allowance for security planning and procedure development | R6: =VLOOKUP($F6,Inputs!$D$6:$E$41,2,FALSE) | S6: =VLOOKUP($E6,Inputs!$A$6:$B$13,2,FALSE)*Inputs!$B$2 | T6: =$L6*$S6 | U6: =$L6+$T6
A7: PKG-00::L006 | B7: PKG-00 | C7: DEL-00.06 | D7: L006 | E7: E | F7: PKG-00 | G7: DEL-00.06 | H7: Pre-Works Road Condition Survey - field survey and photo documentation | I7: 1 | J7: LS | K7: 15000 | L7: 15000 | M7: CAD | N7: ALLOWANCE | O7: A-006 | P7: LOW | Q7: Allowance for surveyor services without vendor quote | R7: =VLOOKUP($F7,Inputs!$D$6:$E$41,2,FALSE) | S7: =VLOOKUP($E7,Inputs!$A$6:$B$13,2,FALSE)*Inputs!$B$2 | T7: =$L7*$S7 | U7: =$L7+$T7
A8: PKG-00::L007 | B8: PKG-00 | C8: DEL-00.07 | D8: L007 | E8: E | F8: PKG-00 | G8: DEL-00.07 | H8: Post-Works Road Condition Survey - survey and deficiency closeout | I8: 1 | J8: LS | K8: 18000 | L8: 18000 | M8: CAD | N8: ALLOWANCE | O8: A-007 | P8: LOW | Q8: Allowance for post-construction survey services | R8: =VLOOKUP($F8,Inputs!$D$6:$E$41,2,FALSE) | S8: =VLOOKUP($E8,Inputs!$A$6:$B$13,2,FALSE)*Inputs!$B$2 | T8: =$L8*$S8 | U8: =$L8+$T8
A9: PKG-00::L008 | B9: PKG-00 | C9: DEL-00.07 | D9: L008 | E9: CD | F9: PKG-00 | G9: DEL-00.07 | H9: Road Deficiency Remediation - asphalt patching and restoration work | I9: 1 | J9: LS | K9: 25000 | L9: 25000 | M9: CAD | N9: ALLOWANCE | O9: A-008 | P9: LOW | Q9: Placeholder for road restoration; highly variable based on actual damage | R9: =VLOOKUP($F9,Inputs!$D$6:$E$41,2,FALSE) | S9: =VLOOKUP($E9,Inputs!$A$6:$B$13,2,FALSE)*Inputs!$B$2 | T9: =$L9*$S9 | U9: =$L9+$T9
A10: PKG-00::L009 | B10: PKG-00 | C10: DEL-00.08 | D10: L009 | E10: E | F10: PKG-00 | G10: DEL-00.08 | H10: Temporary Water Supply Design - utility design drawings (3 drawings) | I10: 1 | J10: LS | K10: 10000 | L10: 10000 | M10: CAD | N10: ALLOWANCE | O10: A-009 | P10: LOW | Q10: Allowance for water supply design effort | R10: =VLOOKUP($F10,Inputs!$D$6:$E$41,2,FALSE) | S10: =VLOOKUP($E10,Inputs!$A$6:$B$13,2,FALSE)*Inputs!$B$2 | T10: =$L10*$S10 | U10: =$L10+$T10
A11: PKG-00::L010 | B11: PKG-00 | C11: DEL-00.08 | D11: L010 | E11: MAT | F11: PKG-00 | G11: DEL-00.08 | H11: Temporary Water Supply Materials - pipe fittings backflow preventer valves | I11: 1 | J11: LS | K11: 20000 | L11: 20000 | M11: CAD | N11: ALLOWANCE | O11: A-010 | P11: LOW | Q11: Material allowance without vendor quotes or site layout distances | R11: =VLOOKUP($F11,Inputs!$D$6:$E$41,2,FALSE) | S11: =VLOOKUP($E11,Inputs!$A$6:$B$13,2,FALSE)*Inputs!$B$2 | T11: =$L11*$S11 | U11: =$L11+$T11
A12: PKG-00::L011 | B12: PKG-00 | C12: DEL-00.08 | D12: L011 | E12: CD | F12: PKG-00 | G12: DEL-00.08 | H12: Temporary Water Supply Installation - plumbing labor connection testing | I12: 1 | J12: LS | K12: 25000 | L12: 25000 | M12: CAD | N12: ALLOWANCE | O12: A-010 | P12: LOW | Q12: Installation labor allowance without rate tables | R12: =VLOOKUP($F12,Inputs!$D$6:$E$41,2,FALSE) | S12: =VLOOKUP($E12,Inputs!$A$6:$B$13,2,FALSE)*Inputs!$B$2 | T12: =$L12*$S12 | U12: =$L12+$T12
A13: PKG-00::L012 | B13: PKG-00 | C13: DEL-00.05 | D13: L012 | E13: CD | F13: PKG-00 | G13: DEL-00.05 | H13: Security Gate & Access Control Installation - gate hardware and system install | I13: 1 | J13: LS | K13: 75000 | L13: 75000 | M13: CAD | N13: ALLOWANCE | O13: A-011 | P13: LOW | Q13: Allowance for security equipment and installation | R13: =VLOOKUP($F13,Inputs!$D$6:$E$41,2,FALSE) | S13: =VLOOKUP($E13,Inputs!$A$6:$B$13,2,FALSE)*Inputs!$B$2 | T13: =$L13*$S13 | U13: =$L13+$T13
A14: PKG-00::L013 | B14: PKG-00 | D14: L013 | E14: MAT | F14: PKG-00 | H14: Temporary Site Facilities - Materials (office trailers welfare facilities fencing) | I14: 1 | J14: LS | K14: 500000 | L14: 500000 | M14: CAD | N14: ALLOWANCE | O14: A-012 | P14: LOW | Q14: Material component of site facilities allowance; breakdown: trailers $300k fencing $150k misc $50k | R14: =VLOOKUP($F14,Inputs!$D$6:$E$41,2,FALSE) | S14: =VLOOKUP($E14,Inputs!$A$6:$B$13,2,FALSE)*Inputs!$B$2 | T14: =$L14*$S14 | U14: =$L14+$T14
A15: PKG-00::L014 | B15: PKG-00 | D15: L014 | E15: CD | F15: PKG-00 | H15: Temporary Site Infrastructure - Construction (laydown electrical utilities signage) | I15: 1 | J15: LS | K15: 350000 | L15: 350000 | M15: CAD | N15: ALLOWANCE | O15: A-012 | P15: LOW | Q15: Construction component of site infrastructure allowance; breakdown: laydown $150k electrical $120k welfare $80k | R15: =VLOOKUP($F15,Inputs!$D$6:$E$41,2,FALSE) | S15: =VLOOKUP($E15,Inputs!$A$6:$B$13,2,FALSE)*Inputs!$B$2 | T15: =$L15*$S15 | U15: =$L15+$T15
A16: PKG-00::L015 | B16: PKG-00 | D16: L015 | E16: CI | F16: PKG-00 | H16: Security Gate Staffing - construction phase security operations | I16: 1 | J16: LS | K16: 180000 | L16: 180000 | M16: CAD | N16: ALLOWANCE | O16: A-013 | P16: LOW | Q16: 24-month gate staffing allowance (12hr/day 6day/week @ $30/hr); hours TBD from schedule | R16: =VLOOKUP($F16,Inputs!$D$6:$E$41,2,FALSE) | S16: =VLOOKUP($E16,Inputs!$A$6:$B$13,2,FALSE)*Inputs!$B$2 | T16: =$L16*$S16 | U16: =$L16+$T16
A17: PKG-00::L016 | B17: PKG-00 | D17: L016 | E17: CI | F17: PKG-00 | H17: Construction Indirects - field supervision site overhead QA/QC (factor-based) | I17: 1 | J17: LS | K17: 85500 | L17: 85500 | M17: CAD | N17: PARAMETRIC | O17: D-006 | P17: LOW | Q17: 18% of CD base ($475k CD × 0.18); factor from fallback model | R17: =VLOOKUP($F17,Inputs!$D$6:$E$41,2,FALSE) | S17: =VLOOKUP($E17,Inputs!$A$6:$B$13,2,FALSE)*Inputs!$B$2 | T17: =$L17*$S17 | U17: =$L17+$T17
A18: PKG-00::L017 | B18: PKG-00 | D18: L017 | E18: PM | F18: PKG-00 | H18: EPCM / Project Management - PKG-00 allocation (factor-based) | I18: 1 | J18: LS | K18: 75630 | L18: 75630 | M18: CAD | N18: PARAMETRIC | O18: D-006 | P18: MED | Q18: 6% of (CD+CI+MAT) = 6% × ($475k + $265.5k + $520k) = $75.6k; factor from fallback model | R18: =VLOOKUP($F18,Inputs!$D$6:$E$41,2,FALSE) | S18: =VLOOKUP($E18,Inputs!$A$6:$B$13,2,FALSE)*Inputs!$B$2 | T18: =$L18*$S18 | U18: =$L18+$T18
A19: PKG-00::L018 | B19: PKG-00 | D19: L018 | E19: P | F19: PKG-00 | H19: Procurement Services - vendor coordination expediting (factor-based) | I19: 1 | J19: LS | K19: 10400 | L19: 10400 | M19: CAD | N19: PARAMETRIC | O19: D-006 | P19: MED | Q19: 2% of MAT = 2% × $520k; factor from fallback model | R19: =VLOOKUP($F19,Inputs!$D$6:$E$41,2,FALSE) | S19: =VLOOKUP($E19,Inputs!$A$6:$B$13,2,FALSE)*Inputs!$B$2 | T19: =$L19*$S19 | U19: =$L19+$T19
A20: PKG-01::L101 | B20: PKG-01 | C20: DEL-01.01 | D20: L101 | E20: E | F20: PKG-01 | G20: DEL-01.01 | H20: Demolition Design Drawing Set - CAD drafting and production (demolition plans removal sequence disposal location plans ~6 drawings) | I20: 1 | J20: LS | K20: 18000 | L20: 18000 | M20: CAD | N20: ALLOWANCE | O20: A-101 | P20: LOW | Q20: Allowance for demolition drawing production; more complex than site establishment due to phasing and marine interface | R20: =VLOOKUP($F20,Inputs!$D$6:$E$41,2,FALSE) | S20: =VLOOKUP($E20,Inputs!$A$6:$B$13,2,FALSE)*Inputs!$B$2 | T20: =$L20*$S20 | U20: =$L20+$T20
A21: PKG-01::L102 | B21: PKG-01 | C21: DEL-01.02 | D21: L102 | E21: E | F21: PKG-01 | G21: DEL-01.02 | H21: Demolition Technical Specification - specification writing (demolition spec disposal requirements) | I21: 1 | J21: LS | K21: 15000 | L21: 15000 | M21: CAD | N21: ALLOWANCE | O21: A-102 | P21: LOW | Q21: Allowance for specification writing; includes performance materials workmanship and disposal requirements sections | R21: =VLOOKUP($F21,Inputs!$D$6:$E$41,2,FALSE) | S21: =VLOOKUP($E21,Inputs!$A$6:$B$13,2,FALSE)*Inputs!$B$2 | T21: =$L21*$S21 | U21: =$L21+$T21
A22: PKG-01::L103 | B22: PKG-01 | C22: DEL-01.03 | D22: L103 | E22: PM | F22: PKG-01 | G22: DEL-01.03 | H22: Demolition Procedures - method statement and procedure development (5 procedures: general plus Track 6 Dolphin 2 fencing salt tent) | I22: 1 | J22: LS | K22: 25000 | L22: 25000 | M22: CAD | N22: ALLOWANCE | O22: A-103 | P22: LOW | Q22: Allowance for HSE procedure development; Track 6 and Dolphin 2 procedures require specialized content | R22: =VLOOKUP($F22,Inputs!$D$6:$E$41,2,FALSE) | S22: =VLOOKUP($E22,Inputs!$A$6:$B$13,2,FALSE)*Inputs!$B$2 | T22: =$L22*$S22 | U22: =$L22+$T22
A23: PKG-01::L104 | B23: PKG-01 | C23: DEL-01.04 | D23: L104 | E23: E | F23: PKG-01 | G23: DEL-01.04 | H23: Demolition Installation & Test Records - QA/QC documentation setup and record preparation | I23: 1 | J23: LS | K23: 8000 | L23: 8000 | M23: CAD | N23: ALLOWANCE | O23: A-104 | P23: LOW | Q23: Allowance for QA/QC documentation templates record setup and closeout documentation | R23: =VLOOKUP($F23,Inputs!$D$6:$E$41,2,FALSE) | S23: =VLOOKUP($E23,Inputs!$A$6:$B$13,2,FALSE)*Inputs!$B$2 | T23: =$L23*$S23 | U23: =$L23+$T23
A24: PKG-01::L105 | B24: PKG-01 | D24: L105 | E24: CD | F24: PKG-01 | H24: Track 6 Rail Demolition - rail track removal ballast removal tie disposal (assume ~500 LF rail track) | I24: 1 | J24: LS | K24: 175000 | L24: 175000 | M24: CAD | N24: ALLOWANCE | O24: A-105 | P24: LOW | Q24: Placeholder for Track 6 demolition; actual cost depends on track length condition and ballast contamination status | R24: =VLOOKUP($F24,Inputs!$D$6:$E$41,2,FALSE) | S24: =VLOOKUP($E24,Inputs!$A$6:$B$13,2,FALSE)*Inputs!$B$2 | T24: =$L24*$S24 | U24: =$L24+$T24
A25: PKG-01::L106 | B25: PKG-01 | D25: L106 | E25: CD | F25: PKG-01 | H25: Dolphin 2 Marine Demolition - marine structure removal including barge/crane mobilization pile cutting deck removal marine debris control | I25: 1 | J25: LS | K25: 450000 | L25: 450000 | M25: CAD | N25: ALLOWANCE | O25: A-106 | P25: LOW | Q25: Marine demolition requires specialized marine equipment and crew; placeholder based on typical marine pile structure removal - highly variable | R25: =VLOOKUP($F25,Inputs!$D$6:$E$41,2,FALSE) | S25: =VLOOKUP($E25,Inputs!$A$6:$B$13,2,FALSE)*Inputs!$B$2 | T25: =$L25*$S25 | U25: =$L25+$T25
A26: PKG-01::L107 | B26: PKG-01 | D26: L107 | E26: CD | F26: PKG-01 | H26: Fencing Removal - perimeter fencing demolition and disposal (assume ~2000 LF chain-link or similar) | I26: 1 | J26: LS | K26: 35000 | L26: 35000 | M26: CAD | N26: ALLOWANCE | O26: A-107 | P26: LOW | Q26: Placeholder for fencing removal; relatively simple scope but length unknown | R26: =VLOOKUP($F26,Inputs!$D$6:$E$41,2,FALSE) | S26: =VLOOKUP($E26,Inputs!$A$6:$B$13,2,FALSE)*Inputs!$B$2 | T26: =$L26*$S26 | U26: =$L26+$T26
A27: PKG-01::L108 | B27: PKG-01 | D27: L108 | E27: CD | F27: PKG-01 | H27: Salt Tent Dismantling - building structure demolition foundation removal site restoration | I27: 1 | J27: LS | K27: 125000 | L27: 125000 | M27: CAD | N27: ALLOWANCE | O27: A-108 | P27: LOW | Q27: Placeholder for salt tent demolition; cost depends on structure type size and foundation requirements | R27: =VLOOKUP($F27,Inputs!$D$6:$E$41,2,FALSE) | S27: =VLOOKUP($E27,Inputs!$A$6:$B$13,2,FALSE)*Inputs!$B$2 | T27: =$L27*$S27 | U27: =$L27+$T27
A28: PKG-01::L109 | B28: PKG-01 | D28: L109 | E28: MAT | F28: PKG-01 | H28: Demolition Materials and Temporary Works - protection barriers dust control erosion control disposal containers | I28: 1 | J28: LS | K28: 40000 | L28: 40000 | M28: CAD | N28: ALLOWANCE | O28: A-109 | P28: LOW | Q28: Materials allowance for temporary works and protection measures during demolition | R28: =VLOOKUP($F28,Inputs!$D$6:$E$41,2,FALSE) | S28: =VLOOKUP($E28,Inputs!$A$6:$B$13,2,FALSE)*Inputs!$B$2 | T28: =$L28*$S28 | U28: =$L28+$T28
A29: PKG-01::L110 | B29: PKG-01 | D29: L110 | E29: CD | F29: PKG-01 | H29: Hazardous Materials Contingency Placeholder - potential asbestos lead or contaminated materials (hazmat survey pending) | I29: 1 | J29: LS | K29: 75000 | L29: 75000 | M29: CAD | N29: ALLOWANCE | O29: A-110 | P29: LOW | Q29: Contingency placeholder per D-016; hazmat presence unknown - if survey confirms hazmat actual costs may be significantly higher | R29: =VLOOKUP($F29,Inputs!$D$6:$E$41,2,FALSE) | S29: =VLOOKUP($E29,Inputs!$A$6:$B$13,2,FALSE)*Inputs!$B$2 | T29: =$L29*$S29 | U29: =$L29+$T29
A30: PKG-01::L111 | B30: PKG-01 | D30: L111 | E30: CD | F30: PKG-01 | H30: Waste Disposal and Hauling - demolition waste transport to disposal/recycling facilities (concrete steel wood rail materials) | I30: 1 | J30: LS | K30: 95000 | L30: 95000 | M30: CAD | N30: ALLOWANCE | O30: A-111 | P30: LOW | Q30: Placeholder for waste disposal; actual cost depends on material volumes disposal distances and tipping fees | R30: =VLOOKUP($F30,Inputs!$D$6:$E$41,2,FALSE) | S30: =VLOOKUP($E30,Inputs!$A$6:$B$13,2,FALSE)*Inputs!$B$2 | T30: =$L30*$S30 | U30: =$L30+$T30
A31: PKG-01::L112 | B31: PKG-01 | D31: L112 | E31: CI | F31: PKG-01 | H31: Construction Indirects - field supervision safety oversight QA/QC coordination (factor-based) | I31: 1 | J31: LS | K31: 171000 | L31: 171000 | M31: CAD | N31: PARAMETRIC | O31: D-017 | P31: LOW | Q31: 18% of CD base ($950k CD x 0.18 = $171k); factor from fallback model per D-017 | R31: =VLOOKUP($F31,Inputs!$D$6:$E$41,2,FALSE) | S31: =VLOOKUP($E31,Inputs!$A$6:$B$13,2,FALSE)*Inputs!$B$2 | T31: =$L31*$S31 | U31: =$L31+$T31
A32: PKG-01::L113 | B32: PKG-01 | D32: L113 | E32: PM | F32: PKG-01 | H32: EPCM / Project Management - PKG-01 allocation (factor-based) | I32: 1 | J32: LS | K32: 69660 | L32: 69660 | M32: CAD | N32: PARAMETRIC | O32: D-017 | P32: MED | Q32: 6% of (CD+CI+MAT) = 6% x ($950k + $171k + $40k) = $69.7k; factor from fallback model per D-017 | R32: =VLOOKUP($F32,Inputs!$D$6:$E$41,2,FALSE) | S32: =VLOOKUP($E32,Inputs!$A$6:$B$13,2,FALSE)*Inputs!$B$2 | T32: =$L32*$S32 | U32: =$L32+$T32
A33: PKG-01::L114 | B33: PKG-01 | D33: L114 | E33: P | F33: PKG-01 | H33: Procurement Services - vendor coordination expediting (factor-based) | I33: 1 | J33: LS | K33: 800 | L33: 800 | M33: CAD | N33: PARAMETRIC | O33: D-017 | P33: MED | Q33: 2% of MAT = 2% x $40k = $800; factor from fallback model per D-017 | R33: =VLOOKUP($F33,Inputs!$D$6:$E$41,2,FALSE) | S33: =VLOOKUP($E33,Inputs!$A$6:$B$13,2,FALSE)*Inputs!$B$2 | T33: =$L33*$S33 | U33: =$L33+$T33
A34: PKG-02::L001 | B34: PKG-02 | C34: DEL-02.01 | D34: L001 | E34: E | F34: PKG-02 | G34: DEL-02.01 | H34: Earthworks Design Drawing Set - CAD drafting (grading plans cut/fill plans ground improvement sections) | I34: 1 | J34: LS | K34: 25000 | L34: 25000 | M34: CAD | N34: ALLOWANCE | O34: A-001 | P34: LOW | Q34: ~8-10 sheets at $3k/sheet average | R34: =VLOOKUP($F34,Inputs!$D$6:$E$41,2,FALSE) | S34: =VLOOKUP($E34,Inputs!$A$6:$B$13,2,FALSE)*Inputs!$B$2 | T34: =$L34*$S34 | U34: =$L34+$T34
A35: PKG-02::L002 | B35: PKG-02 | C35: DEL-02.02 | D35: L002 | E35: E | F35: PKG-02 | G35: DEL-02.02 | H35: Earthworks Technical Specification - specification writing (earthworks ground improvement geotextile specs) | I35: 1 | J35: LS | K35: 8000 | L35: 8000 | M35: CAD | N35: ALLOWANCE | O35: A-002 | P35: LOW | Q35: ~50 hours at $150/hr | R35: =VLOOKUP($F35,Inputs!$D$6:$E$41,2,FALSE) | S35: =VLOOKUP($E35,Inputs!$A$6:$B$13,2,FALSE)*Inputs!$B$2 | T35: =$L35*$S35 | U35: =$L35+$T35
A36: PKG-02::L003 | B36: PKG-02 | C36: DEL-02.03 | D36: L003 | E36: E | F36: PKG-02 | G36: DEL-02.03 | H36: Earthworks Design Calculations - cut/fill calculations bearing capacity settlement analysis | I36: 1 | J36: LS | K36: 12000 | L36: 12000 | M36: CAD | N36: ALLOWANCE | O36: A-003 | P36: LOW | Q36: ~70 hours at $175/hr | R36: =VLOOKUP($F36,Inputs!$D$6:$E$41,2,FALSE) | S36: =VLOOKUP($E36,Inputs!$A$6:$B$13,2,FALSE)*Inputs!$B$2 | T36: =$L36*$S36 | U36: =$L36+$T36
A37: PKG-02::L004 | B37: PKG-02 | C37: DEL-02.04 | D37: L004 | E37: E | F37: PKG-02 | G37: DEL-02.04 | H37: Geotechnical Investigation - field drilling program (15-20 boreholes 15-25m deep) | I37: 1 | J37: LS | K37: 100000 | L37: 100000 | M37: CAD | N37: ALLOWANCE | O37: A-004 | P37: LOW | Q37: Drilling mobilization boreholes sampling monitoring wells | R37: =VLOOKUP($F37,Inputs!$D$6:$E$41,2,FALSE) | S37: =VLOOKUP($E37,Inputs!$A$6:$B$13,2,FALSE)*Inputs!$B$2 | T37: =$L37*$S37 | U37: =$L37+$T37
A38: PKG-02::L005 | B38: PKG-02 | C38: DEL-02.04 | D38: L005 | E38: E | F38: PKG-02 | G38: DEL-02.04 | H38: Geotechnical Laboratory Testing - soil classification strength compaction tests | I38: 1 | J38: LS | K38: 25000 | L38: 25000 | M38: CAD | N38: ALLOWANCE | O38: A-005 | P38: LOW | Q38: Full lab program for design parameters | R38: =VLOOKUP($F38,Inputs!$D$6:$E$41,2,FALSE) | S38: =VLOOKUP($E38,Inputs!$A$6:$B$13,2,FALSE)*Inputs!$B$2 | T38: =$L38*$S38 | U38: =$L38+$T38
A39: PKG-02::L006 | B39: PKG-02 | C39: DEL-02.04 | D39: L006 | E39: E | F39: PKG-02 | G39: DEL-02.04 | H39: Geotechnical Reporting - investigation report and ground improvement design | I39: 1 | J39: LS | K39: 18000 | L39: 18000 | M39: CAD | N39: ALLOWANCE | O39: A-006 | P39: LOW | Q39: ~100 hours engineering time | R39: =VLOOKUP($F39,Inputs!$D$6:$E$41,2,FALSE) | S39: =VLOOKUP($E39,Inputs!$A$6:$B$13,2,FALSE)*Inputs!$B$2 | T39: =$L39*$S39 | U39: =$L39+$T39
A40: PKG-02::L007 | B40: PKG-02 | C40: DEL-02.05 | D40: L007 | E40: E | F40: PKG-02 | G40: DEL-02.05 | H40: Topographic Survey - site survey including utility locates (~7 ha) | I40: 1 | J40: LS | K40: 55000 | L40: 55000 | M40: CAD | N40: ALLOWANCE | O40: A-007 | P40: LOW | Q40: Survey and CAD deliverables | R40: =VLOOKUP($F40,Inputs!$D$6:$E$41,2,FALSE) | S40: =VLOOKUP($E40,Inputs!$A$6:$B$13,2,FALSE)*Inputs!$B$2 | T40: =$L40*$S40 | U40: =$L40+$T40
...

Sheet BOE_Reference
A1: BOE reference tables (from Project_BOE.md) | H1: Home
A3: Executive summary metrics | D3: Counts
A4: Metric | B4: Value | D4: Packages | E4: 36
A5: **Total Estimate** | B5: **$117.1M CAD** | D5: Deliverables | E5: 202
A6: Base Estimate | B6: $92,416,406 CAD | D6: Line items | E6: 867
A7: Contingency | B7: ~$24.7M CAD (~26.7% blended)
A8: Currency | B8: CAD (Canadian dollars)
A9: Pricing Date | B9: January 2026
A10: Estimate Class | B10: Class 5 (Order of Magnitude)
A11: Overall Confidence | B11: LOW
A12: Accuracy Range | B12: -30% / +50%
A14: Package coverage summary
A15: Category | B15: Packages | C15: Base Cost | D15: % of Total
A16: Site & Civil | B16: PKG-00 to PKG-04 | C16: $12.5M | D16: 13.5%
A17: Structural | B17: PKG-05 to PKG-09 | C17: $13.7M | D17: 14.8%
A18: Mechanical | B18: PKG-10 to PKG-16 | C18: $36.0M | D18: 39.0%
A19: Electrical & I&C | B19: PKG-17 to PKG-20 | C19: $8.4M | D19: 9.1%
A20: Buildings & Protection | B20: PKG-21 to PKG-26 | C20: $9.3M | D20: 10.1%
A21: Project Execution | B21: PKG-27 to PKG-35 | C21: $12.5M | D21: 13.5%
A22: **TOTAL** | B22: **36 Packages** | C22: **$92.4M** | D22: **100%**
A25: CBS summary
A26: CBS | B26: Description | C26: Amount (CAD) | D26: % of Total
A27: MAT | B27: Materials | C27: $41,045,785 | D27: 44.4%
A28: CD | B28: Construction Directs | C28: $26,933,520 | D28: 29.1%
A29: E | B29: Engineering | C29: $8,640,165 | D29: 9.4%
A30: PM | B30: Project Management | C30: $5,821,748 | D30: 6.3%
A31: CI | B31: Construction Indirects | C31: $5,816,043 | D31: 6.3%
A32: COM | B32: Commissioning | C32: $3,004,199 | D32: 3.3%
A33: P | B33: Procurement | C33: $921,946 | D33: 1.0%
A34: FRT | B34: Freight | C34: $233,000 | D34: 0.3%
A35: **BASE TOTAL** | C35: **$92,416,406** | D35: **100%**
A37: Pricing method distribution
A38: Method | B38: Line Items | C38: % of Items | D38: Remarks
A39: ALLOWANCE | B39: 689 | C39: 79.5% | D39: Lump-sum placeholders without vendor validation
A40: PARAMETRIC | B40: 154 | C40: 17.8% | D40: Factor-based calculations (indirects, PM, etc.)
A41: RATE_TABLE | B41: 11 | C41: 1.3% | D41: Limited rate table pricing
A42: QUOTE | B42: 0 | C42: 0% | D42: No vendor quotes available
A43: **TOTAL** | B43: **867** | C43: **100%**
A46: Contingency by CBS (as stated in BOE)
A47: CBS | B47: Base (CAD) | C47: Contingency Rate | D47: Contingency (CAD)
...

Sheet Inputs
A1: Model Inputs / Lookups | L1: Home
A2: Contingency scaling factor | B2: 1 | C2: (1.00 = use BOE bucket rates as-is)
A4: Contingency rates by CBS (from BOE §7.2) | D4: Package category mapping (from BOE §2.3) | G4: Package descriptions (from BOE §12)
A5: CBS | B5: Rate | D5: Package | E5: PackageCategory | G5: Package | H5: Description | I5: Confidence
A6: E | B6: 0.15 | D6: PKG-00 | E6: Site & Civil | G6: PKG-00 | H6: Site Establishment | I6: LOW
A7: PM | B7: 0.15 | D7: PKG-01 | E7: Site & Civil | G7: PKG-01 | H7: Demolition & Removals | I7: LOW
A8: P | B8: 0.15 | D8: PKG-02 | E8: Site & Civil | G8: PKG-02 | H8: Earthworks & Ground Improvement | I8: LOW
A9: MAT | B9: 0.2 | D9: PKG-03 | E9: Site & Civil | G9: PKG-03 | H9: Underground Utilities & Drainage | I9: LOW
A10: FRT | B10: 0.2 | D10: PKG-04 | E10: Site & Civil | G10: PKG-04 | H10: Pavement & Surfacing | I10: LOW
A11: CD | B11: 0.25 | D11: PKG-05 | E11: Structural | G11: PKG-05 | H11: Concrete Structures | I11: LOW
A12: CI | B12: 0.25 | D12: PKG-06 | E12: Structural | G12: PKG-06 | H12: Structural Steelwork | I12: LOW
A13: COM | B13: 0.3 | D13: PKG-07 | E13: Structural | G13: PKG-07 | H13: Rail Works | I13: LOW
D14: PKG-08 | E14: Structural | G14: PKG-08 | H14: Marine Structures | I14: LOW
D15: PKG-09 | E15: Structural | G15: PKG-09 | H15: Marine Outfitting | I15: LOW
D16: PKG-10 | E16: Mechanical | G16: PKG-10 | H16: Railcar Unloading System | I16: LOW
D17: PKG-11 | E17: Mechanical | G17: PKG-11 | H17: Marine Loading System | I17: LOW
D18: PKG-12 | E18: Mechanical | G18: PKG-12 | H18: Product Transfer & Metering | I18: LOW
D19: PKG-13 | E19: Mechanical | G19: PKG-13 | H19: Storage Tanks | I19: LOW
D20: PKG-14 | E20: Mechanical | G20: PKG-14 | H20: Process Piping | I20: LOW
D21: PKG-15 | E21: Mechanical | G21: PKG-15 | H21: Pumps & Rotating Equipment | I21: LOW-MED
D22: PKG-16 | E22: Mechanical | G22: PKG-16 | H22: Valves & Specialty Equipment | I22: LOW
D23: PKG-17 | E23: Electrical & I&C | G23: PKG-17 | H23: Electrical Power Distribution | I23: LOW
D24: PKG-18 | E24: Electrical & I&C | G24: PKG-18 | H24: Lighting | I24: LOW
D25: PKG-19 | E25: Electrical & I&C | G25: PKG-19 | H25: Control Systems | I25: LOW
... D41: PKG-35 | E41: Project Execution | G41: PKG-35 | H41: Training & Handover | I41: LOW
