Workbook

Sheet Dashboard
B2: Estimating Dashboard
B3: Project: | C3: Town of Penhold -- Public Services Building (PSB)
B4: Currency / Base Year: | C4: CAD / 2024 | E4: As of: | F4: 2026-02-18
B6: Filters (optional) | J6: Chart Drivers (auto)
B7: Package | C7: All | E7: Method | F7: All | H7: =IF(C7="All","*",C7) -> * | J7: Method | K7: Amount
B8: Deliverable | C8: All | E8: Confidence | F8: All | H8: =IF(C8="All","*",C8) -> * | J8: RATE_TABLE | K8: =SUMIFS(Detail_Lines!$L$2:$L$267,Detail_Lines!$C$2:$C$267,$H$7,Detail_Lines!$B$2:$B$267,$H$8,Detail_Lines!$P$2:$P$267,$H$10,Detail_Lines!$N$2:$N$267,J8) -> 6216696
H9: =IF(F7="All","*",F7) -> * | J9: ALLOWANCE | K9: =SUMIFS(Detail_Lines!$L$2:$L$267,Detail_Lines!$C$2:$C$267,$H$7,Detail_Lines!$B$2:$B$267,$H$8,Detail_Lines!$P$2:$P$267,$H$10,Detail_Lines!$N$2:$N$267,J9) -> 692150
H10: =IF(F8="All","*",F8) -> * | J10: PARAMETRIC | K10: =SUMIFS(Detail_Lines!$L$2:$L$267,Detail_Lines!$C$2:$C$267,$H$7,Detail_Lines!$B$2:$B$267,$H$8,Detail_Lines!$P$2:$P$267,$H$10,Detail_Lines!$N$2:$N$267,J10) -> 292400
B11: Project Total (excl. subtotals) | E11: Selected Scope Total | J11: QUOTE | K11: =SUMIFS(Detail_Lines!$L$2:$L$267,Detail_Lines!$C$2:$C$267,$H$7,Detail_Lines!$B$2:$B$267,$H$8,Detail_Lines!$P$2:$P$267,$H$10,Detail_Lines!$N$2:$N$267,J11) -> 18600
B12: =SUMIFS(Summary_WBS!$C$2:$C$37,Summary_WBS!$B$2:$B$37,"<>SUBTOTAL") -> 7219846 | E12: =SUMIFS(Detail_Lines!$L$2:$L$267,Detail_Lines!$C$2:$C$267,$H$7,Detail_Lines!$B$2:$B$267,$H$8,Detail_Lines!$N$2:$N$267,$H$9,Detail_Lines!$P$2:$P$267,$H$10) -> 7219846 | J12: Total | K12: =SUM(K8:K11) -> 7219846
J14: Confidence | K14: Amount
J15: HIGH | K15: =SUMIFS(Detail_Lines!$L$2:$L$267,Detail_Lines!$C$2:$C$267,$H$7,Detail_Lines!$B$2:$B$267,$H$8,Detail_Lines!$N$2:$N$267,$H$9,Detail_Lines!$P$2:$P$267,J15) -> 30770
B16: Allowance Share | E16: Low-Confidence Share | J16: MED | K16: =SUMIFS(Detail_Lines!$L$2:$L$267,Detail_Lines!$C$2:$C$267,$H$7,Detail_Lines!$B$2:$B$267,$H$8,Detail_Lines!$N$2:$N$267,$H$9,Detail_Lines!$P$2:$P$267,J16) -> 6028056
B17: =IFERROR(SUMIFS(Detail_Lines!$L$2:$L$267,Detail_Lines!$C$2:$C$267,$H$7,Detail_Lines!$B$2:$B$267,$H$8,Detail_Lines!$N$2:$N$267,"ALLOWANCE",Detail_Lines!$P$2:$P$267,$H$10)/E12,0) -> 0.095867696 | E17: =IFERROR(SUMIFS(Detail_Lines!$L$2:$L$267,Detail_Lines!$C$2:$C$267,$H$7,Detail_Lines!$B$2:$B$267,$H$8,Detail_Lines!$P$2:$P$267,"LOW",Detail_Lines!$N$2:$N$267,$H$9)/E12,0) -> 0.15823329 | J17: MEDIUM | K17: =SUMIFS(Detail_Lines!$L$2:$L$267,Detail_Lines!$C$2:$C$267,$H$7,Detail_Lines!$B$2:$B$267,$H$8,Detail_Lines!$N$2:$N$267,$H$9,Detail_Lines!$P$2:$P$267,J17) -> 18600
J18: LOW | K18: =SUMIFS(Detail_Lines!$L$2:$L$267,Detail_Lines!$C$2:$C$267,$H$7,Detail_Lines!$B$2:$B$267,$H$8,Detail_Lines!$N$2:$N$267,$H$9,Detail_Lines!$P$2:$P$267,J18) -> 1142420
J19: Total | K19: =SUM(K15:K18) -> 7219846
B21: Priced Lines (scope) | E21: Deliverables (line count) in scope | J21: Package | K21: Subtotal
B22: =COUNTIFS(Detail_Lines!$C$2:$C$267,$H$7,Detail_Lines!$B$2:$B$267,$H$8,Detail_Lines!$N$2:$N$267,$H$9,Detail_Lines!$P$2:$P$267,$H$10) -> 266 | E22: =SUMIFS(Summary_WBS!$D$2:$D$37,Summary_WBS!$A$2:$A$37,$H$7,Summary_WBS!$B$2:$B$37,$H$8,Summary_WBS!$B$2:$B$37,"<>SUBTOTAL") -> 266 | J22: PKG-001 | K22: =SUMIFS(Summary_WBS!$C$2:$C$37,Summary_WBS!$A$2:$A$37,J22,Summary_WBS!$B$2:$B$37,"SUBTOTAL") -> 464450
J23: PKG-002 | K23: =SUMIFS(Summary_WBS!$C$2:$C$37,Summary_WBS!$A$2:$A$37,J23,Summary_WBS!$B$2:$B$37,"SUBTOTAL") -> 4239304
J24: PKG-003 | K24: =SUMIFS(Summary_WBS!$C$2:$C$37,Summary_WBS!$A$2:$A$37,J24,Summary_WBS!$B$2:$B$37,"SUBTOTAL") -> 1657342
J25: PKG-004 | K25: =SUMIFS(Summary_WBS!$C$2:$C$37,Summary_WBS!$A$2:$A$37,J25,Summary_WBS!$B$2:$B$37,"SUBTOTAL") -> 464750
J26: PKG-005 | K26: =SUMIFS(Summary_WBS!$C$2:$C$37,Summary_WBS!$A$2:$A$37,J26,Summary_WBS!$B$2:$B$37,"SUBTOTAL") -> 394000
J27: Total | K27: =SUM(K22:K26) -> 7219846
J29: Risk Heatmap (count)
J30: Likelihood \ Impact | K30: LOW | L30: MEDIUM | M30: HIGH
J31: LOW | K31: =COUNTIFS(Risks!$B$2:$B$41,$H$8,Risks!$I$2:$I$41,J31,Risks!$J$2:$J$41,K30) -> 8 | L31: =COUNTIFS(Risks!$B$2:$B$41,$H$8,Risks!$I$2:$I$41,J31,Risks!$J$2:$J$41,L30) -> 0 | M31: =COUNTIFS(Risks!$B$2:$B$41,$H$8,Risks!$I$2:$I$41,J31,Risks!$J$2:$J$41,M30) -> 1
J32: MEDIUM | K32: =COUNTIFS(Risks!$B$2:$B$41,$H$8,Risks!$I$2:$I$41,J32,Risks!$J$2:$J$41,K30) -> 0 | L32: =COUNTIFS(Risks!$B$2:$B$41,$H$8,Risks!$I$2:$I$41,J32,Risks!$J$2:$J$41,L30) -> 13 | M32: =COUNTIFS(Risks!$B$2:$B$41,$H$8,Risks!$I$2:$I$41,J32,Risks!$J$2:$J$41,M30) -> 1
J33: HIGH | K33: =COUNTIFS(Risks!$B$2:$B$41,$H$8,Risks!$I$2:$I$41,J33,Risks!$J$2:$J$41,K30) -> 0 | L33: =COUNTIFS(Risks!$B$2:$B$41,$H$8,Risks!$I$2:$I$41,J33,Risks!$J$2:$J$41,L30) -> 1 | M33: =COUNTIFS(Risks!$B$2:$B$41,$H$8,Risks!$I$2:$I$41,J33,Risks!$J$2:$J$41,M30) -> 6
B44: Data sheets:
B45: Detail Lines
B46: WBS Summary
B47: CBS Summary
B48: WBS×CBS Matrix
B49: BOE Index
B50: Coverage
B51: Assumptions
B52: Risks
B53: BOE Collection

Sheet Detail_Lines
A1: LineUID | B1: FromDeliverableID | C1: FromPackageID | D1: LineID | E1: CBS | F1: WBS_PackageID | G1: WBS_DeliverableID | H1: Description | I1: Qty | J1: Unit | K1: UnitRate | L1: Amount | M1: Currency | N1: Method | O1: SourceRef | P1: Confidence | Q1: Notes | R1: SourceSnapshot
A2: DEL-01-01::L-001 | B2: DEL-01-01 | C2: PKG-001 | D2: L-001 | E2: MGMT | F2: PKG-001 | G2: DEL-01-01 | H2: Project Manager — PM oversight across full 18-month construction phase (~7 hr/wk) | I2: 120 | J2: hr | K2: 175 | L2: 21000 | M2: CAD | N2: RATE_TABLE | O2: Rate: Professional_Staff_Rates.csv row R-02 ($175/hr); Hours: Level_of_Effort.csv row DEL-01-01/R-02 (120 hr); Duration basis: Assumed_Project_Parameters.csv PP-01 (18 months) | P2: MED | Q2: PM oversight across full 18-month construction phase; ~7 hr/wk | R2: EST_DEL-01-01_2026-02-18_1200
A3: DEL-01-01::L-002 | B3: DEL-01-01 | C3: PKG-001 | D3: L-002 | E3: MGMT | F3: PKG-001 | G3: DEL-01-01 | H3: Design Manager — Design phase leadership 4 months + periodic review during construction | I3: 80 | J3: hr | K3: 165 | L3: 13200 | M3: CAD | N3: RATE_TABLE | O3: Rate: Professional_Staff_Rates.csv row R-03 ($165/hr); Hours: Level_of_Effort.csv row DEL-01-01/R-03 (80 hr); Duration basis: Assumed_Project_Parameters.csv PP-02 (4 months design) | P3: MED | Q3: Design phase leadership 4 months; periodic review during construction | R3: EST_DEL-01-01_2026-02-18_1200
A4: DEL-01-01::L-003 | B4: DEL-01-01 | C4: PKG-001 | D4: L-003 | E4: DESIGN | F4: PKG-001 | G4: DEL-01-01 | H4: Architect (Project) — Design review and QA/QC review cycles | I4: 40 | J4: hr | K4: 145 | L4: 5800 | M4: CAD | N4: RATE_TABLE | O4: Rate: Professional_Staff_Rates.csv row R-04 ($145/hr); Hours: Level_of_Effort.csv row DEL-01-01/R-04 (40 hr) | P4: MED | Q4: Design review; QA/QC review cycles — management function not discipline design production | R4: EST_DEL-01-01_2026-02-18_1200
A5: DEL-01-01::L-004 | B5: DEL-01-01 | C5: PKG-001 | D5: L-004 | E5: ADMIN | F5: PKG-001 | G5: DEL-01-01 | H5: Administrative / Document Control — Document management full project duration (~3.5 hr/wk) | I5: 60 | J5: hr | K5: 80 | L5: 4800 | M5: CAD | N5: RATE_TABLE | O5: Rate: Professional_Staff_Rates.csv row R-24 ($80/hr); Hours: Level_of_Effort.csv row DEL-01-01/R-24 (60 hr); Duration basis: Assumed_Project_Parameters.csv PP-01 (18 months) | P5: MED | Q5: Document management full project duration; ~3.5 hr/wk | R5: EST_DEL-01-01_2026-02-18_1200
A6: DEL-01-02::L-001 | B6: DEL-01-02 | C6: PKG-001 | D6: L-001 | E6: MGMT.PROJ_CONTROLS | F6: PKG-001 | G6: DEL-01-02 | H6: Scheduler — schedule development (40h) + monthly updates (2h/mo x 18mo = 36h) + closeout | I6: 80 | J6: hr | K6: 130 | L6: 10400 | M6: CAD | N6: RATE_TABLE | O6: Professional_Staff_Rates.csv row R-17; Level_of_Effort.csv row DEL-01-02 R-17 | P6: MED | Q6: Rate: R-17 Scheduler $130/hr; Hours: LOE basis (PARAMETRIC) see DEC-EST-001 | R6: EST_DEL-01-02_2026-02-18_2100
A7: DEL-01-02::L-002 | B7: DEL-01-02 | C7: PKG-001 | D7: L-002 | E7: MGMT.PROJ_CONTROLS | F7: PKG-001 | G7: DEL-01-02 | H7: Project Manager — schedule review + reporting oversight | I7: 20 | J7: hr | K7: 175 | L7: 3500 | M7: CAD | N7: RATE_TABLE | O7: Professional_Staff_Rates.csv row R-02; Level_of_Effort.csv row DEL-01-02 R-02 | P7: MED | Q7: Rate: R-02 PM $175/hr; Hours: LOE basis (PARAMETRIC) see DEC-EST-001 | R7: EST_DEL-01-02_2026-02-18_2100
A8: DEL-01-02::L-003 | B8: DEL-01-02 | C8: PKG-001 | D8: L-003 | E8: MGMT.PROJ_CONTROLS | F8: PKG-001 | G8: DEL-01-02 | H8: Scheduling software / tools — project scheduling license (18-month project) | I8: 1 | J8: LS | K8: 3500 | L8: 3500 | M8: CAD | N8: ALLOWANCE | O8: Parametric allowance — P6/MS Project license for 18-month project | P8: LOW | Q8: Previously TBD; resolved as parametric allowance per ORCHESTRATOR TBD resolution pass; see DEC-EST-005 | R8: EST_DEL-01-02_2026-02-18_2100
A9: DEL-01-03::L-0103-001 | B9: DEL-01-03 | C9: PKG-001 | D9: L-0103-001 | E9: CBS-LABOUR-SAFETY | F9: PKG-001 | G9: DEL-01-03 | H9: Safety Officer - H&S plan development and site safety management | I9: 60 | J9: hr | K9: 110 | L9: 6600 | M9: CAD | N9: RATE_TABLE | O9: Professional_Staff_Rates.csv (R-20) + Level_of_Effort.csv (DEL-01-03 R-20) | P9: MED | Q9: 20h plan development + ~2.5h/wk x 16wk active site safety; rate $110/hr per rate table | R9: EST_DEL-01-03_2026-02-18_2100
A10: DEL-01-03::L-0103-002 | B10: DEL-01-03 | C10: PKG-001 | D10: L-0103-002 | E10: CBS-LABOUR-ADMIN | F10: PKG-001 | G10: DEL-01-03 | H10: Administrative / Document Control - Safety documentation filing | I10: 8 | J10: hr | K10: 80 | L10: 640 | M10: CAD | N10: RATE_TABLE | O10: Professional_Staff_Rates.csv (R-24) + Level_of_Effort.csv (DEL-01-03 R-24) | P10: MED | Q10: Safety doc filing support; rate $80/hr per rate table | R10: EST_DEL-01-03_2026-02-18_2100
A11: DEL-01-03::L-0103-003 | B11: DEL-01-03 | C11: PKG-001 | D11: L-0103-003 | E11: CBS-TRAINING | F11: PKG-001 | G11: DEL-01-03 | H11: Training costs - site orientation and safety training materials for 18-month project | I11: 1 | J11: LS | K11: 4500 | L11: 4500 | M11: CAD | N11: ALLOWANCE | O11: Parametric allowance — site orientation + safety training for 30-40 workers over 18-month project | P11: LOW | Q11: Previously TBD; resolved as parametric allowance per ORCHESTRATOR TBD resolution pass; covers WHMIS/first aid/confined space training sessions + materials | R11: EST_DEL-01-03_2026-02-18_2100
A12: DEL-01-03::L-0103-004 | B12: DEL-01-03 | C12: PKG-001 | D12: L-0103-004 | E12: CBS-SUPPLIES | F12: PKG-001 | G12: DEL-01-03 | H12: PPE and signage supplies - hard hats + vests + glasses + first aid kits + site signage | I12: 1 | J12: LS | K12: 3500 | L12: 3500 | M12: CAD | N12: ALLOWANCE | O12: Parametric allowance — PPE and site safety signage for 18-month construction project | P12: LOW | Q12: Previously TBD; resolved as parametric allowance per ORCHESTRATOR TBD resolution pass; covers standard PPE inventory + site safety signage package | R12: EST_DEL-01-03_2026-02-18_2100
A13: DEL-01-04::L-01 | B13: DEL-01-04 | C13: PKG-001 | D13: L-01 | E13: 01-MGMT | F13: PKG-001 | G13: DEL-01-04 | H13: Project Manager -- permit applications; inspection coordination; AHJ liaison | I13: 40 | J13: hr | K13: 175 | L13: 7000 | M13: CAD | N13: RATE_TABLE | O13: Level_of_Effort.csv row DEL-01-04/R-02 + Professional_Staff_Rates.csv R-02 | P13: MED | Q13: 40h per Level_of_Effort.csv; $175/hr per Professional_Staff_Rates.csv | R13: EST_DEL-01-04_2026-02-18_1400
... A267: DEL-05-07::L-0507-001 | B267: DEL-05-07 | C267: PKG-005 | D267: L-0507-001 | E267: FF&E | F267: PKG-005 | G267: DEL-05-07_Optional-FFandE-Allowance | H267: FF&E cash allowance (furniture fixtures and equipment) - fixed per DEC-005 | I267: 1 | J267: LS | K267: 20000 | L267: 20000 | M267: CAD | N267: ALLOWANCE | O267: _PriceSources/Optional_Items_Pricing.csv row OPT-18; DEC-005 | P267: HIGH | Q267: Fixed $20k cash allowance. DB allocates: Meeting/Training $8k; Lunchroom $6k; Reception $3k; Misc $3k. Excludes connected appliances (DEL-05-06 scope). | R267: EST_DEL-05-07_2026-02-18_2200

Sheet Summary_WBS
A1: WBS_PackageID | B1: WBS_DeliverableID | C1: Amount_Total_CAD | D1: LineCount | E1: TBD_Count | F1: Notes
A2: PKG-001 | B2: DEL-01-01 | C2: 44800 | D2: 4 | E2: 0
A3: PKG-001 | B3: DEL-01-02 | C3: 17400 | D3: 3 | E3: 0
A4: PKG-001 | B4: DEL-01-03 | C4: 15240 | D4: 4 | E4: 0
A5: PKG-001 | B5: DEL-01-04 | C5: 79910 | D5: 7 | E5: 0
A6: PKG-001 | B6: DEL-01-05 | C6: 19750 | D6: 2 | E6: 0
A7: PKG-001 | B7: DEL-01-06 | C7: 263700 | D7: 4 | E7: 0
A8: PKG-001 | B8: DEL-01-07 | C8: 23650 | D8: 3 | E8: 0
A9: PKG-002 | B9: DEL-02-01 | C9: 168329 | D9: 10 | E9: 0
A10: PKG-002 | B10: DEL-02-02 | C10: 279279 | D10: 38 | E10: 0
A11: PKG-002 | B11: DEL-02-03 | C11: 212396 | D11: 32 | E11: 0
A12: PKG-002 | B12: DEL-02-04 | C12: 1721269 | D12: 28 | E12: 0
A13: PKG-002 | B13: DEL-02-05 | C13: 1014095 | D13: 16 | E13: 0
... A31: PKG-005 | B31: DEL-05-07 | C31: 20000 | D31: 1 | E31: 0
A32: --- Package Subtotals ---
A33: PKG-001 | B33: SUBTOTAL | C33: 464450 | D33: 27 | E33: 0
A34: PKG-002 | B34: SUBTOTAL | C34: 4239304 | D34: 142 | E34: 0
A35: PKG-003 | B35: SUBTOTAL | C35: 1657342 | D35: 54 | E35: 0
A36: PKG-004 | B36: SUBTOTAL | C36: 464750 | D36: 26 | E36: 0
A37: PKG-005 | B37: SUBTOTAL | C37: 394000 | D37: 17 | E37: 0

Sheet Summary_CBS
A1: CBS | B1: Amount_Total_CAD | C1: LineCount | D1: TBD_Count | E1: Notes
A2: 01-CMGT | B2: 203700 | C2: 2 | D2: 0
A3: 01-FEES | B3: 71950 | C3: 5 | D3: 0
A4: 01-MGMT | B4: 7960 | C4: 2 | D4: 0
A5: 01-SITE | B5: 60000 | C5: 2 | D5: 0
A6: 02-Sitework | B6: 11140 | C6: 2 | D6: 0
A7: 03-02-CLR | B7: 32010 | C7: 2 | D7: 0
A8: 03-02-DRN | B8: 74500 | C8: 3 | D8: 0
A9: 03-02-DSN | B9: 11514 | C9: 1 | D9: 0
A10: 03-02-ESC | B10: 22000 | C10: 1 | D10: 0
A11: 03-02-EW | B11: 178038 | C11: 5 | D11: 0
A12: 03-02-FIN | B12: 110000 | C12: 1 | D12: 0
A13: 03-02-GEO | B13: 32000 | C13: 1 | D13: 0
... A107: REGULATORY_FEES | B107: 16970 | C107: 3 | D107: 0

Sheet WBSxCBS_Matrix
A1: WBS_PackageID | B1: WBS_DeliverableID | C1: CBS | D1: Currency | E1: Amount_Total | F1: LineCount | G1: ProvenanceCompletenessPct | H1: Notes
A2: PKG-001 | B2: DEL-01-01 | C2: ADMIN | D2: CAD | E2: 4800 | F2: 1 | G2: 100%
A3: PKG-001 | B3: DEL-01-01 | C3: DESIGN | D3: CAD | E3: 5800 | F3: 1 | G3: 100%
A4: PKG-001 | B4: DEL-01-01 | C4: MGMT | D4: CAD | E4: 34200 | F4: 2 | G4: 100%
A5: PKG-001 | B5: DEL-01-02 | C5: MGMT.PROJ_CONTROLS | D5: CAD | E5: 17400 | F5: 3 | G5: 100%
A6: PKG-001 | B6: DEL-01-03 | C6: CBS-LABOUR-ADMIN | D6: CAD | E6: 640 | F6: 1 | G6: 100%
A7: PKG-001 | B7: DEL-01-03 | C7: CBS-LABOUR-SAFETY | D7: CAD | E7: 6600 | F7: 1 | G7: 100%
A8: PKG-001 | B8: DEL-01-03 | C8: CBS-SUPPLIES | D8: CAD | E8: 3500 | F8: 1 | G8: 100%
A9: PKG-001 | B9: DEL-01-03 | C9: CBS-TRAINING | D9: CAD | E9: 4500 | F9: 1 | G9: 100%
A10: PKG-001 | B10: DEL-01-04 | C10: 01-FEES | D10: CAD | E10: 71950 | F10: 5 | G10: 100%
A11: PKG-001 | B11: DEL-01-04 | C11: 01-MGMT | D11: CAD | E11: 7960 | F11: 2 | G11: 100%
A12: PKG-001 | B12: DEL-01-05 | C12: ADMIN | D12: CAD | E12: 4000 | F12: 1 | G12: 100%
A13: PKG-001 | B13: DEL-01-05 | C13: PM | D13: CAD | E13: 15750 | F13: 1 | G13: 100%
... A111: PKG-005 | B111: DEL-05-07_Optional-FFandE-Allowance | C111: FF&E | D111: CAD | E111: 20000 | F111: 1 | G111: 100%

Sheet BOE_Index
A1: FromDeliverableID | B1: FromPackageID | C1: DeclaredBasis | D1: FallbackPolicy | E1: AllowMixed | F1: ActualMethodsUsed | G1: RunStatus | H1: RunContextPath
A2: DEL-01-01 | B2: PKG-001 | C2: RATE_TABLE | D2: STRICT | E2: FALSE | F2: RATE_TABLE | G2: OK | H2: /Users/ryan/ai-env/projects/chirality-app-test/test/execution-6a/_Estimates/EST_DEL-01-01_2026-02-18_1200/Run_Context.md
A3: DEL-01-02 | B3: PKG-001 | C3: RATE_TABLE | D3: ALLOW_ALLOWANCE | E3: TRUE | F3: ALLOWANCE, RATE_TABLE | G3: WARNINGS | H3: /Users/ryan/ai-env/projects/chirality-app-test/test/execution-6a/_Estimates/EST_DEL-01-02_2026-02-18_2100/Run_Context.md
A4: DEL-01-03 | B4: PKG-001 | C4: RATE_TABLE | D4: ALLOW_ALLOWANCE | E4: TRUE | F4: ALLOWANCE, RATE_TABLE | G4: WARNINGS | H4: /Users/ryan/ai-env/projects/chirality-app-test/test/execution-6a/_Estimates/EST_DEL-01-03_2026-02-18_2100/Run_Context.md
A5: DEL-01-04 | B5: PKG-001 | C5: RATE_TABLE | D5: ALLOW_ALLOWANCE | E5: TRUE | F5: ALLOWANCE, RATE_TABLE | G5: WARNINGS | H5: /Users/ryan/ai-env/projects/chirality-app-test/test/execution-6a/_Estimates/EST_DEL-01-04_2026-02-18_1400/Run_Context.md
A6: DEL-01-05 | B6: PKG-001 | C6: RATE_TABLE | D6: STRICT | E6: FALSE | F6: RATE_TABLE | G6: WARNINGS | H6: /Users/ryan/ai-env/projects/chirality-app-test/test/execution-6a/_Estimates/EST_DEL-01-05_2026-02-18_0000/Run_Context.md
A7: DEL-01-06 | B7: PKG-001 | C7: RATE_TABLE | D7: ALLOW_ALLOWANCE | E7: TRUE | F7: ALLOWANCE, RATE_TABLE | G7: WARNINGS | H7: /Users/ryan/ai-env/projects/chirality-app-test/test/execution-6a/_Estimates/EST_DEL-01-06_2026-02-18_2100/Run_Context.md
A8: DEL-01-07 | B8: PKG-001 | C8: RATE_TABLE | D8: STRICT | E8: FALSE | F8: RATE_TABLE | G8: OK | H8: /Users/ryan/ai-env/projects/chirality-app-test/test/execution-6a/_Estimates/EST_DEL-01-07_2026-02-18_1830/Run_Context.md
A9: DEL-02-01 | B9: PKG-002 | C9: RATE_TABLE | D9: STRICT | E9: FALSE | F9: RATE_TABLE | G9: WARNINGS | H9: /Users/ryan/ai-env/projects/chirality-app-test/test/execution-6a/_Estimates/EST_DEL-02-01_2026-02-18_2100/Run_Context.md
A10: DEL-02-02 | B10: PKG-002 | C10: RATE_TABLE | D10: ALLOW_ALLOWANCE | E10: TRUE | F10: ALLOWANCE, RATE_TABLE | G10: WARNINGS | H10: /Users/ryan/ai-env/projects/chirality-app-test/test/execution-6a/_Estimates/EST_DEL-02-02_2026-02-18_1036/Run_Context.md
A11: DEL-02-03 | B11: PKG-002 | C11: RATE_TABLE | D11: ALLOW_ALLOWANCE | E11: TRUE | F11: ALLOWANCE, RATE_TABLE | G11: WARNINGS | H11: /Users/ryan/ai-env/projects/chirality-app-test/test/execution-6a/_Estimates/EST_DEL-02-03_2026-02-18_1100/Run_Context.md
A12: DEL-02-04 | B12: PKG-002 | C12: RATE_TABLE | D12: STRICT | E12: FALSE | F12: RATE_TABLE | G12: WARNINGS | H12: /Users/ryan/ai-env/projects/chirality-app-test/test/execution-6a/_Estimates/EST_DEL-02-04_2026-02-18_1130/Run_Context.md
A13: DEL-02-05 | B13: PKG-002 | C13: RATE_TABLE | D13: STRICT | E13: FALSE | F13: RATE_TABLE | G13: OK | H13: /Users/ryan/ai-env/projects/chirality-app-test/test/execution-6a/_Estimates/EST_DEL-02-05_2026-02-18_1400/Run_Context.md
... A31: DEL-05-07 | B31: PKG-005 | C31: ALLOWANCE | D31: STRICT | E31: FALSE | F31: ALLOWANCE | G31: OK | H31: /Users/ryan/ai-env/projects/chirality-app-test/test/execution-6a/_Estimates/EST_DEL-05-07_2026-02-18_2200/Run_Context.md

Sheet Coverage
A1: FromPackageID | B1: FromDeliverableID | C1: FromDeliverableName | D1: DetailPath | E1: RunContextPath | F1: AssumptionsPath | G1: RisksPath | H1: SchemaStatus | I1: Notes
A2: PKG-001 | B2: DEL-01-01 | C2: Integrated Design Management & Submission Packages | D2: /Users/ryan/ai-env/projects/chirality-app-test/test/execution-6a/_Estimates/EST_DEL-01-01_2026-02-18_1200/Detail.csv | E2: /Users/ryan/ai-env/projects/chirality-app-test/test/execution-6a/_Estimates/EST_DEL-01-01_2026-02-18_1200/Run_Context.md | F2: /Users/ryan/ai-env/projects/chirality-app-test/test/execution-6a/_Estimates/EST_DEL-01-01_2026-02-18_1200/Assumptions_Log.md | G2: NOT_PRESENT | H2: OK
A3: PKG-001 | B3: DEL-01-02 | C3: Baseline Schedule, Updates & Reporting | D3: /Users/ryan/ai-env/projects/chirality-app-test/test/execution-6a/_Estimates/EST_DEL-01-02_2026-02-18_2100/Detail.csv | E3: /Users/ryan/ai-env/projects/chirality-app-test/test/execution-6a/_Estimates/EST_DEL-01-02_2026-02-18_2100/Run_Context.md | F3: /Users/ryan/ai-env/projects/chirality-app-test/test/execution-6a/_Estimates/EST_DEL-01-02_2026-02-18_2100/Assumptions_Log.md | G3: NOT_PRESENT | H3: OK
A4: PKG-001 | B4: DEL-01-03 | C4: Health & Safety Plan | D4: /Users/ryan/ai-env/projects/chirality-app-test/test/execution-6a/_Estimates/EST_DEL-01-03_2026-02-18_2100/Detail.csv | E4: /Users/ryan/ai-env/projects/chirality-app-test/test/execution-6a/_Estimates/EST_DEL-01-03_2026-02-18_2100/Run_Context.md | F4: /Users/ryan/ai-env/projects/chirality-app-test/test/execution-6a/_Estimates/EST_DEL-01-03_2026-02-18_2100/Assumptions_Log.md | G4: NOT_PRESENT | H4: OK
A5: PKG-001 | B5: DEL-01-04 | C5: Permitting, Inspections & AHJ Coordination | D5: /Users/ryan/ai-env/projects/chirality-app-test/test/execution-6a/_Estimates/EST_DEL-01-04_2026-02-18_1400/Detail.csv | E5: /Users/ryan/ai-env/projects/chirality-app-test/test/execution-6a/_Estimates/EST_DEL-01-04_2026-02-18_1400/Run_Context.md | F5: /Users/ryan/ai-env/projects/chirality-app-test/test/execution-6a/_Estimates/EST_DEL-01-04_2026-02-18_1400/Assumptions_Log.md | G5: NOT_PRESENT | H5: OK
A6: PKG-001 | B6: DEL-01-05 | C6: Meetings, Documentation & Change Control | D6: /Users/ryan/ai-env/projects/chirality-app-test/test/execution-6a/_Estimates/EST_DEL-01-05_2026-02-18_0000/Detail.csv | E6: /Users/ryan/ai-env/projects/chirality-app-test/test/execution-6a/_Estimates/EST_DEL-01-05_2026-02-18_0000/Run_Context.md | F6: /Users/ryan/ai-env/projects/chirality-app-test/test/execution-6a/_Estimates/EST_DEL-01-05_2026-02-18_0000/Assumptions_Log.md | G6: NOT_PRESENT | H6: OK
A7: PKG-001 | B7: DEL-01-06 | C7: Site Supervision, Logistics & Housekeeping | D7: /Users/ryan/ai-env/projects/chirality-app-test/test/execution-6a/_Estimates/EST_DEL-01-06_2026-02-18_2100/Detail.csv | E7: /Users/ryan/ai-env/projects/chirality-app-test/test/execution-6a/_Estimates/EST_DEL-01-06_2026-02-18_2100/Run_Context.md | F7: /Users/ryan/ai-env/projects/chirality-app-test/test/execution-6a/_Estimates/EST_DEL-01-06_2026-02-18_2100/Assumptions_Log.md | G7: NOT_PRESENT | H7: OK
A8: PKG-001 | B8: DEL-01-07 | C8: Commissioning, Closeout & Warranty | D8: /Users/ryan/ai-env/projects/chirality-app-test/test/execution-6a/_Estimates/EST_DEL-01-07_2026-02-18_1830/Detail.csv | E8: /Users/ryan/ai-env/projects/chirality-app-test/test/execution-6a/_Estimates/EST_DEL-01-07_2026-02-18_1830/Run_Context.md | F8: /Users/ryan/ai-env/projects/chirality-app-test/test/execution-6a/_Estimates/EST_DEL-01-07_2026-02-18_1830/Assumptions_Log.md | G8: NOT_PRESENT | H8: OK
A9: PKG-002 | B9: DEL-02-01 | C9: Architectural Program, Layout & Code Planning | D9: /Users/ryan/ai-env/projects/chirality-app-test/test/execution-6a/_Estimates/EST_DEL-02-01_2026-02-18_2100/Detail.csv | E9: /Users/ryan/ai-env/projects/chirality-app-test/test/execution-6a/_Estimates/EST_DEL-02-01_2026-02-18_2100/Run_Context.md | F9: /Users/ryan/ai-env/projects/chirality-app-test/test/execution-6a/_Estimates/EST_DEL-02-01_2026-02-18_2100/Assumptions_Log.md | G9: NOT_PRESENT | H9: OK
A10: PKG-002 | B10: DEL-02-02 | C10: Firehall Apparatus Bays & Support Spaces | D10: /Users/ryan/ai-env/projects/chirality-app-test/test/execution-6a/_Estimates/EST_DEL-02-02_2026-02-18_1036/Detail.csv | E10: /Users/ryan/ai-env/projects/chirality-app-test/test/execution-6a/_Estimates/EST_DEL-02-02_2026-02-18_1036/Run_Context.md | F10: /Users/ryan/ai-env/projects/chirality-app-test/test/execution-6a/_Estimates/EST_DEL-02-02_2026-02-18_1036/Assumptions_Log.md | G10: NOT_PRESENT | H10: OK
A11: PKG-002 | B11: DEL-02-03 | C11: Public Works Shop Bays & Support Spaces | D11: /Users/ryan/ai-env/projects/chirality-app-test/test/execution-6a/_Estimates/EST_DEL-02-03_2026-02-18_1100/Detail.csv | E11: /Users/ryan/ai-env/projects/chirality-app-test/test/execution-6a/_Estimates/EST_DEL-02-03_2026-02-18_1100/Run_Context.md | F11: /Users/ryan/ai-env/projects/chirality-app-test/test/execution-6a/_Estimates/EST_DEL-02-03_2026-02-18_1100/Assumptions_Log.md | G11: /Users/ryan/ai-env/projects/chirality-app-test/test/execution-6a/_Estimates/EST_DEL-02-03_2026-02-18_1100/Risk_Register.md | H11: OK
A12: PKG-002 | B12: DEL-02-04 | C12: Structure, Envelope, Roof & Overhead Doors | D12: /Users/ryan/ai-env/projects/chirality-app-test/test/execution-6a/_Estimates/EST_DEL-02-04_2026-02-18_1130/Detail.csv | E12: /Users/ryan/ai-env/projects/chirality-app-test/test/execution-6a/_Estimates/EST_DEL-02-04_2026-02-18_1130/Run_Context.md | F12: /Users/ryan/ai-env/projects/chirality-app-test/test/execution-6a/_Estimates/EST_DEL-02-04_2026-02-18_1130/Assumptions_Log.md | G12: NOT_PRESENT | H12: OK
A13: PKG-002 | B13: DEL-02-05 | C13: Mechanical, Plumbing, Ventilation & Exhaust | D13: /Users/ryan/ai-env/projects/chirality-app-test/test/execution-6a/_Estimates/EST_DEL-02-05_2026-02-18_1400/Detail.csv | E13: /Users/ryan/ai-env/projects/chirality-app-test/test/execution-6a/_Estimates/EST_DEL-02-05_2026-02-18_1400/Run_Context.md | F13: /Users/ryan/ai-env/projects/chirality-app-test/test/execution-6a/_Estimates/EST_DEL-02-05_2026-02-18_1400/Assumptions_Log.md | G13: /Users/ryan/ai-env/projects/chirality-app-test/test/execution-6a/_Estimates/EST_DEL-02-05_2026-02-18_1400/Risk_Register.md | H13: OK
... A28: PKG-005 | B28: DEL-05-04 | C28: Option: Security Camera System | D28: /Users/ryan/ai-env/projects/chirality-app-test/test/execution-6a/_Estimates/EST_DEL-05-04_2026-02-18_1800/Detail.csv | E28: /Users/ryan/ai-env/projects/chirality-app-test/test/execution-6a/_Estimates/EST_DEL-05-04_2026-02-18_1800/Run_Context.md | F28: /Users/ryan/ai-env/projects/chirality-app-test/test/execution-6a/_Estimates/EST_DEL-05-04_2026-02-18_1800/Assumptions_Log.md | G28: /Users/ryan/ai-env/projects/chirality-app-test/test/execution-6a/_Estimates/EST_DEL-05-04_2026-02-18_1800/Risk_Register.md | H28: OK
A29: PKG-005 | B29: DEL-05-05 | C29: Option: Town Branding Signage | D29: /Users/ryan/ai-env/projects/chirality-app-test/test/execution-6a/_Estimates/EST_DEL-05-05_2026-02-18_1800/Detail.csv | E29: /Users/ryan/ai-env/projects/chirality-app-test/test/execution-6a/_Estimates/EST_DEL-05-05_2026-02-18_1800/Run_Context.md | F29: /Users/ryan/ai-env/projects/chirality-app-test/test/execution-6a/_Estimates/EST_DEL-05-05_2026-02-18_1800/Assumptions_Log.md | G29: /Users/ryan/ai-env/projects/chirality-app-test/test/execution-6a/_Estimates/EST_DEL-05-05_2026-02-18_1800/Risk_Register.md | H29: OK | I29: 2 mutually exclusive scenarios (primary=$12k non-illuminated; alternate=$22k illuminated)
A30: PKG-005 | B30: DEL-05-06 | C30: Option: Kitchen & Laundry Appliances | D30: /Users/ryan/ai-env/projects/chirality-app-test/test/execution-6a/_Estimates/EST_DEL-05-06_2026-02-18_1900/Detail.csv | E30: /Users/ryan/ai-env/projects/chirality-app-test/test/execution-6a/_Estimates/EST_DEL-05-06_2026-02-18_1900/Run_Context.md | F30: /Users/ryan/ai-env/projects/chirality-app-test/test/execution-6a/_Estimates/EST_DEL-05-06_2026-02-18_1900/Assumptions_Log.md | G30: /Users/ryan/ai-env/projects/chirality-app-test/test/execution-6a/_Estimates/EST_DEL-05-06_2026-02-18_1900/Risk_Register.md | H30: OK
A31: PKG-005 | B31: DEL-05-07 | C31: Option: FF&E Cash Allowance | D31: /Users/ryan/ai-env/projects/chirality-app-test/test/execution-6a/_Estimates/EST_DEL-05-07_2026-02-18_2200/Detail.csv | E31: /Users/ryan/ai-env/projects/chirality-app-test/test/execution-6a/_Estimates/EST_DEL-05-07_2026-02-18_2200/Run_Context.md | F31: /Users/ryan/ai-env/projects/chirality-app-test/test/execution-6a/_Estimates/EST_DEL-05-07_2026-02-18_2200/Assumptions_Log.md | G31: NOT_PRESENT | H31: OK

Sheet Assumptions
A1: AssumptionUID | B1: FromDeliverableID | C1: AssumptionID | D1: Title | E1: Assumption | F1: Source | G1: SourcePath
A2: DEL-01-01::ASM-001 | B2: DEL-01-01 | C2: ASM-001 | D2: Project Duration | E2: Construction duration is 18 months (NTP to Substantial Performance). | F2: Assumed_Project_Parameters.csv, PP-01 (Source=ASSUMPTION, Confidence=MEDIUM). | G2: /Users/ryan/ai-env/projects/chirality-app-test/test/execution-6a/_Estimates/EST_DEL-01-01_2026-02-18_1200/Assumptions_Log.md
A3: DEL-01-01::ASM-002 | B3: DEL-01-01 | C3: ASM-002 | D3: Design Phase Duration | E3: Design phase duration is 4 months. | F3: Assumed_Project_Parameters.csv, PP-02 (Source=ASSUMPTION, Confidence=MEDIUM). | G3: /Users/ryan/ai-env/projects/chirality-app-test/test/execution-6a/_Estimates/EST_DEL-01-01_2026-02-18_1200/Assumptions_Log.md
A4: DEL-01-01::ASM-003 | B4: DEL-01-01 | C4: ASM-003 | D4: Staff Rates Are Market-Basis Estimates | E4: Hourly rates in Professional_Staff_Rates.csv are representative market rates for Alberta, not negotiated/contracted rates. | F4: Professional_Staff_Rates.csv, Basis=MARKET for all roles, Confidence=MEDIUM. | G4: /Users/ryan/ai-env/projects/chirality-app-test/test/execution-6a/_Estimates/EST_DEL-01-01_2026-02-18_1200/Assumptions_Log.md
A5: DEL-01-01::ASM-004 | B5: DEL-01-01 | C5: ASM-004 | D5: Level of Effort Is Parametric | E5: Hour estimates in Level_of_Effort.csv are parametric (based on typical project effort distribution), not based on detailed task-level work breakdown. | F5: Level_of_Effort.csv, Basis=PARAMETRIC for all rows. | G5: /Users/ryan/ai-env/projects/chirality-app-test/test/execution-6a/_Estimates/EST_DEL-01-01_2026-02-18_1200/Assumptions_Log.md
A6: DEL-01-01::ASM-005 | B6: DEL-01-01 | C6: ASM-005 | D6: No Escalation or Inflation Factor | E6: Rates are current (no escalation applied for future periods). | F6: Professional_Staff_Rates.csv contains no escalation column or date-based adjustment. | G6: /Users/ryan/ai-env/projects/chirality-app-test/test/execution-6a/_Estimates/EST_DEL-01-01_2026-02-18_1200/Assumptions_Log.md
A7: DEL-01-02::ASM-001 | B7: DEL-01-02 | C7: ASM-001 | D7: Scheduler Hours Based on 18-Month Duration | E7: Scheduler Hours Based on 18-Month Duration | G7: /Users/ryan/ai-env/projects/chirality-app-test/test/execution-6a/_Estimates/EST_DEL-01-02_2026-02-18_2100/Assumptions_Log.md
A8: DEL-01-02::ASM-002 | B8: DEL-01-02 | C8: ASM-002 | D8: PM Hours for Schedule Oversight Are Incremental | E8: PM Hours for Schedule Oversight Are Incremental | G8: /Users/ryan/ai-env/projects/chirality-app-test/test/execution-6a/_Estimates/EST_DEL-01-02_2026-02-18_2100/Assumptions_Log.md
A9: DEL-01-02::ASM-003 | B9: DEL-01-02 | C9: ASM-003 | D9: Staff Rates Are Blended/Market Rates | E9: Staff Rates Are Blended/Market Rates | G9: /Users/ryan/ai-env/projects/chirality-app-test/test/execution-6a/_Estimates/EST_DEL-01-02_2026-02-18_2100/Assumptions_Log.md
A10: DEL-01-02::ASM-004 | B10: DEL-01-02 | C10: ASM-004 | D10: Software/Tools Cost (UPDATED) | E10: Scheduling software/tools cost estimated at $3,500 CAD as a parametric allowance for an 18-month project. Based on typical P6 Cloud or MS Project Online licensing. | F10: Parametric estimate; no vendor quote or rate table | G10: /Users/ryan/ai-env/projects/chirality-app-test/test/execution-6a/_Estimates/EST_DEL-01-02_2026-02-18_2100/Assumptions_Log.md
A11: DEL-01-07::ASM-0107 | B11: DEL-01-07 | C11: ASM-0107 | D11: -001 Construction duration of 18 months | E11: -001 Construction duration of 18 months | F11: Assumed_Project_Parameters.csv, row PP-01. | G11: /Users/ryan/ai-env/projects/chirality-app-test/test/execution-6a/_Estimates/EST_DEL-01-07_2026-02-18_1830/Assumptions_Log.md
A12: DEL-01-07::ASM-0107 | B12: DEL-01-07 | C12: ASM-0107 | D12: -002 Commissioning Lead hours breakdown | E12: -002 Commissioning Lead hours breakdown | F12: Level_of_Effort.csv, row DEL-01-07/R-21, Notes column. | G12: /Users/ryan/ai-env/projects/chirality-app-test/test/execution-6a/_Estimates/EST_DEL-01-07_2026-02-18_1830/Assumptions_Log.md
A13: DEL-01-07::ASM-0107 | B13: DEL-01-07 | C13: ASM-0107 | D13: -003 Warranty period of 12 months | E13: -003 Warranty period of 12 months | F13: Datasheet.md > Deficiency Process Attributes; RFP section 7.6. | G13: /Users/ryan/ai-env/projects/chirality-app-test/test/execution-6a/_Estimates/EST_DEL-01-07_2026-02-18_1830/Assumptions_Log.md
A14: DEL-01-07::ASM-0107 | B14: DEL-01-07 | C14: ASM-0107 | D14: -004 Document deliverables quantity | E14: -004 Document deliverables quantity | F14: Datasheet.md > Delivery Format Requirements; RFP section 7.5. | G14: /Users/ryan/ai-env/projects/chirality-app-test/test/execution-6a/_Estimates/EST_DEL-01-07_2026-02-18_1830/Assumptions_Log.md
A15: DEL-01-07::ASM-0107 | B15: DEL-01-07 | C15: ASM-0107 | D15: -005 Rates are current and un-escalated | E15: -005 Rates are current and un-escalated | F15: Professional_Staff_Rates.csv, Basis=MARKET. | G15: /Users/ryan/ai-env/projects/chirality-app-test/test/execution-6a/_Estimates/EST_DEL-01-07_2026-02-18_1830/Assumptions_Log.md
A16: DEL-01-07::ASM-0107 | B16: DEL-01-07 | C16: ASM-0107 | D16: -006 No disbursements or third-party costs included | E16: -006 No disbursements or third-party costs included | F16: PRICE_SOURCES contain only labor rates and hours; no disbursement schedule provided. | G16: /Users/ryan/ai-env/projects/chirality-app-test/test/execution-6a/_Estimates/EST_DEL-01-07_2026-02-18_1830/Assumptions_Log.md
A17: DEL-02-04::ASM-01 | B17: DEL-02-04 | C17: ASM-01 | D17: Building Footprint Area | E17: Main PSB ground floor area is 18,000 sf (1,672 m2), based on functional program layout with 4 fire bays + 4 PW bays + office/admin + support spaces, with approximate dimensions ~160 ft x 110 ft. | F17: PP-05 (Assumed_Project_Parameters.csv) | G17: /Users/ryan/ai-env/projects/chirality-app-test/test/execution-6a/_Estimates/EST_DEL-02-04_2026-02-18_1130/Assumptions_Log.md
A18: DEL-02-04::ASM-02 | B18: DEL-02-04 | C18: ASM-02 | D18: Building Perimeter | E18: Building perimeter is approximately 540 lf (165 lm), based on ~160 ft x 110 ft rectangular footprint. | F18: Derived from PP-05 dimensional notes | G18: /Users/ryan/ai-env/projects/chirality-app-test/test/execution-6a/_Estimates/EST_DEL-02-04_2026-02-18_1130/Assumptions_Log.md
A19: DEL-02-04::ASM-03 | B19: DEL-02-04 | C19: ASM-03 | D19: Bay Area | E19: Total bay area (fire apparatus + PW shop) is approximately 12,000 sf (1,115 m2), based on 8 bays at approximately 1,500 sf each. | F19: Derived from PP-11 (4 fire bays) + PP-12 (4 PW bays); bay size estimated from 16x16 ft doors + circulation/work space | G19: /Users/ryan/ai-env/projects/chirality-app-test/test/execution-6a/_Estimates/EST_DEL-02-04_2026-02-18_1130/Assumptions_Log.md
A20: DEL-02-04::ASM-04 | B20: DEL-02-04 | C20: ASM-04 | D20: Office/Shared Area | E20: Office and shared space area is approximately 6,000 sf (557 m2), calculated as 18,000 sf total minus 12,000 sf bay area. | F20: Derived from PP-05 minus ASM-03 | G20: /Users/ryan/ai-env/projects/chirality-app-test/test/execution-6a/_Estimates/EST_DEL-02-04_2026-02-18_1130/Assumptions_Log.md
A21: DEL-02-04::ASM-05 | B21: DEL-02-04 | C21: ASM-05 | D21: Average Wall Height | E21: Average exterior wall height is 6.5 m (21.3 ft), accommodating 16 ft minimum clear door height plus structural depth and parapet. | F21: Derived from SOW-0215 (16 ft min clear height) plus assumed structural depth and parapet | G21: /Users/ryan/ai-env/projects/chirality-app-test/test/execution-6a/_Estimates/EST_DEL-02-04_2026-02-18_1130/Assumptions_Log.md
... A39: DEL-02-04::ASM-23 | B39: DEL-02-04 | C39: ASM-23 | D39: Sump Rough-In Rate | E39: Sump rough-in (blockout in structural slab) is estimated at $750 per location. This covers formwork, blockout framing, and PVC sleeve cast into the 200mm slab. The sump assembly, oil/water separator, and plumbing connection costs are excluded (DEL-02-05 scope per cost ownership rules). | F39: Not directly from rate tables. Informed by MS-10 (bay sump assembly at $4,500 complete) with rough-in estimated as approximately 15-20% of complete assembly cost. This is a LOW confidence assumption. | G39: /Users/ryan/ai-env/projects/chirality-app-test/test/execution-6a/_Estimates/EST_DEL-02-04_2026-02-18_1130/Assumptions_Log.md
A40: DEL-02-07::ASM-001 | B40: DEL-02-07 | C40: ASM-001 | D40: Generator Runtime = 72 Hours | E40: Generator Runtime = 72 Hours | G40: /Users/ryan/ai-env/projects/chirality-app-test/test/execution-6a/_Estimates/EST_DEL-02-07_2026-02-18_1600/Assumptions_Log.md
A41: DEL-02-07::ASM-002 | B41: DEL-02-07 | C41: ASM-002 | D41: Generator Size = 100-150 kW | E41: Generator Size = 100-150 kW | G41: /Users/ryan/ai-env/projects/chirality-app-test/test/execution-6a/_Estimates/EST_DEL-02-07_2026-02-18_1600/Assumptions_Log.md
A42: DEL-02-07::ASM-003 | B42: DEL-02-07 | C42: ASM-003 | D42: Diesel Fuel Type | E42: Diesel Fuel Type | G42: /Users/ryan/ai-env/projects/chirality-app-test/test/execution-6a/_Estimates/EST_DEL-02-07_2026-02-18_1600/Assumptions_Log.md
A43: DEL-02-07::ASM-004 | B43: DEL-02-07 | C43: ASM-004 | D43: Single Generator (Not Redundant) | E43: Single Generator (Not Redundant) | G43: /Users/ryan/ai-env/projects/chirality-app-test/test/execution-6a/_Estimates/EST_DEL-02-07_2026-02-18_1600/Assumptions_Log.md
A44: DEL-02-07::ASM-005 | B44: DEL-02-07 | C44: ASM-005 | D44: Emergency Distribution Scope | E44: Emergency Distribution Scope | G44: /Users/ryan/ai-env/projects/chirality-app-test/test/execution-6a/_Estimates/EST_DEL-02-07_2026-02-18_1600/Assumptions_Log.md
A45: DEL-02-07::ASM-006 | B45: DEL-02-07 | C45: ASM-006 | D45: Door Backup Mechanism — 8 Doors at $2,000 Each | E45: Door Backup Mechanism — 8 Doors at $2,000 Each | G45: /Users/ryan/ai-env/projects/chirality-app-test/test/execution-6a/_Estimates/EST_DEL-02-07_2026-02-18_1600/Assumptions_Log.md
A46: DEL-02-07::ASM-007 | B46: DEL-02-07 | C46: ASM-007 | D46: Installation Labour Hours | E46: Installation Labour Hours | G46: /Users/ryan/ai-env/projects/chirality-app-test/test/execution-6a/_Estimates/EST_DEL-02-07_2026-02-18_1600/Assumptions_Log.md
A47: DEL-02-07::ASM-008 | B47: DEL-02-07 | C47: ASM-008 | D47: Design Fee Basis | E47: Design Fee Basis | G47: /Users/ryan/ai-env/projects/chirality-app-test/test/execution-6a/_Estimates/EST_DEL-02-07_2026-02-18_1600/Assumptions_Log.md
A48: DEL-04-02::ASM-01 | B48: DEL-04-02 | C48: ASM-01 | D48: Overhead Door Supply Price Includes Opener | E48: Overhead Door Supply Price Includes Opener | G48: /Users/ryan/ai-env/projects/chirality-app-test/test/execution-6a/_Estimates/EST_DEL-04-02_2026-02-18_1100/Assumptions_Log.md
A49: DEL-04-02::ASM-02 | B49: DEL-04-02 | C49: ASM-02 | D49: Person Doors are Standard Single-Leaf Commercial | E49: Person Doors are Standard Single-Leaf Commercial | G49: /Users/ryan/ai-env/projects/chirality-app-test/test/execution-6a/_Estimates/EST_DEL-04-02_2026-02-18_1100/Assumptions_Log.md
A50: DEL-04-02::ASM-03 | B50: DEL-04-02 | C50: ASM-03 | D50: Overhead Door Hardware Supplement | E50: Overhead Door Hardware Supplement | G50: /Users/ryan/ai-env/projects/chirality-app-test/test/execution-6a/_Estimates/EST_DEL-04-02_2026-02-18_1100/Assumptions_Log.md
A51: DEL-04-02::ASM-04 | B51: DEL-04-02 | C51: ASM-04 | D51: Concrete Apron Dimensions | E51: Concrete Apron Dimensions | G51: /Users/ryan/ai-env/projects/chirality-app-test/test/execution-6a/_Estimates/EST_DEL-04-02_2026-02-18_1100/Assumptions_Log.md
... A58: DEL-04-02::ASM-11 | B58: DEL-04-02 | C58: ASM-11 | D58: Weatherproof Light Switch Unit Rate | E58: Weatherproof Light Switch Unit Rate | G58: /Users/ryan/ai-env/projects/chirality-app-test/test/execution-6a/_Estimates/EST_DEL-04-02_2026-02-18_1100/Assumptions_Log.md

Sheet Risks
A1: RiskUID | B1: FromDeliverableID | C1: RiskID | D1: Title | E1: Description | F1: Likelihood | G1: Impact | H1: SourcePath | I1: Likelihood_Level | J1: Impact_Level
A2: DEL-02-03::RSK-001 | B2: DEL-02-03 | C2: RSK-001 | D2: Scope Boundary | E2: Locker room and support space fit-up may be claimed by DEL-02-01 (general interior) during aggregation, resulting in double-counting or gaps at the project level. | F2: MEDIUM | G2: HIGH ($95,060 at risk -- 44.8% of estimate) | H2: /Users/ryan/ai-env/projects/chirality-app-test/test/execution-6a/_Estimates/EST_DEL-02-03_2026-02-18_1100/Risk_Register.md | I2: MEDIUM | J2: HIGH
A3: DEL-02-03::RSK-002 | B3: DEL-02-03 | C3: RSK-002 | D3: Area Uncertainty | E3: Support space areas are assumed, not confirmed. Actual floor plan may differ significantly, especially for locker room (1,200 sf assumed) which drives the largest CBS category. | F3: HIGH | G3: MEDIUM ($15,000 +/- range on locker room lines) | H3: /Users/ryan/ai-env/projects/chirality-app-test/test/execution-6a/_Estimates/EST_DEL-02-03_2026-02-18_1100/Risk_Register.md | I3: HIGH | J3: MEDIUM
A4: DEL-02-03::RSK-003 | B4: DEL-02-03 | C4: RSK-003 | D4: Allowance Accuracy | E4: 5 ALLOWANCE items ($60,500 total) are based on professional judgment, not competitive pricing. Actual costs could vary +/- 40%. | F4: MEDIUM | G4: MEDIUM ($24,000 +/- range) | H4: /Users/ryan/ai-env/projects/chirality-app-test/test/execution-6a/_Estimates/EST_DEL-02-03_2026-02-18_1100/Risk_Register.md | I4: MEDIUM | J4: MEDIUM
A5: DEL-02-03::RSK-004 | B5: DEL-02-03 | C5: RSK-004 | D5: Wash Bay Option | E5: If Owner selects optional wash bay (SOW-0500), one PW bay is replaced, reducing bay count from 4 to 3. This reduces bay-area-driven costs by ~25% but adds wash bay conversion costs (separate DEL-05-01 estimate). | F5: LOW | G5: LOW ($13,000 reduction in DEL-02-03) | H5: /Users/ryan/ai-env/projects/chirality-app-test/test/execution-6a/_Estimates/EST_DEL-02-03_2026-02-18_1100/Risk_Register.md | I5: LOW | J5: LOW
A6: DEL-02-03::RSK-005 | B6: DEL-02-03 | C6: RSK-005 | D6: Missing Scope | E6: Items that could arguably belong to DEL-02-03 but were excluded per cost ownership rules: overhead doors ($80,000), HVAC/ventilation ($44,000+), electrical ($14/sf on 8,400 sf = ~$118,000), bay sumps ($18,000). Total excluded scope: ~$260,000. If cost ownership rules change, this estimate would increase significantly. | F6: LOW | G6: HIGH (potential 2x increase) | H6: /Users/ryan/ai-env/projects/chirality-app-test/test/execution-6a/_Estimates/EST_DEL-02-03_2026-02-18_1100/Risk_Register.md | I6: LOW | J6: HIGH
A7: DEL-02-05::RSK-01 | B7: DEL-02-05 | C7: RSK-01 | D7: Fire protection may not be required by AHJ, leading to over-estimation of $108,000 | E7: MEDIUM | F7: HIGH ($108k / 10.7% of total) | G7: AHJ confirmation during design phase; estimate clearly flags this as conditional with LOW confidence | H7: /Users/ryan/ai-env/projects/chirality-app-test/test/execution-6a/_Estimates/EST_DEL-02-05_2026-02-18_1400/Risk_Register.md | I7: HIGH | J7: HIGH
A8: DEL-02-05::RSK-02 | B8: DEL-02-05 | C8: RSK-02 | D8: Actual building zone areas differ from assumed 6,400/6,400/5,200 split | E8: MEDIUM | F8: MEDIUM (~$15-20k per 10% area shift) | G8: Validate against architectural layout from DEL-02-01 when available; rerun estimate | H8: /Users/ryan/ai-env/projects/chirality-app-test/test/execution-6a/_Estimates/EST_DEL-02-05_2026-02-18_1400/Risk_Register.md | I8: MEDIUM | J8: MEDIUM
A9: DEL-02-05::RSK-03 | B9: DEL-02-05 | C9: RSK-03 | D9: Compressed air scope boundary (CON-M-01) resolution could add scope to DEL-02-05 | E9: LOW | F9: MEDIUM ($55,000 if breathing air system added per MS-08) | G9: Brief excludes compressed air from DEL-02-05; if boundary ruling changes, add MS-08 pricing | H9: /Users/ryan/ai-env/projects/chirality-app-test/test/execution-6a/_Estimates/EST_DEL-02-05_2026-02-18_1400/Risk_Register.md | I9: MEDIUM | J9: MEDIUM
A10: DEL-02-05::RSK-04 | B10: DEL-02-05 | C10: RSK-04 | D10: BAS/controls scope may be broader or narrower than full-building application | E10: LOW | F10: MEDIUM ($20k-$72k range depending on coverage) | G10: Confirm BAS scope during design; adjust L-11 area as needed | H10: /Users/ryan/ai-env/projects/chirality-app-test/test/execution-6a/_Estimates/EST_DEL-02-05_2026-02-18_1400/Risk_Register.md | I10: MEDIUM | J10: MEDIUM
A11: DEL-02-07::RISK-001 | B11: DEL-02-07 | C11: RISK-001 | D11: Generator System Cost Exceeds Allowance | E11: Generator System Cost Exceeds Allowance | H11: /Users/ryan/ai-env/projects/chirality-app-test/test/execution-6a/_Estimates/EST_DEL-02-07_2026-02-18_1600/Risk_Register.md
A12: DEL-02-07::RISK-002 | B12: DEL-02-07 | C12: RISK-002 | D12: Scope Creep on Essential Loads List | E12: Scope Creep on Essential Loads List | H12: /Users/ryan/ai-env/projects/chirality-app-test/test/execution-6a/_Estimates/EST_DEL-02-07_2026-02-18_1600/Risk_Register.md
A13: DEL-02-07::RISK-003 | B13: DEL-02-07 | C13: RISK-003 | D13: Double-Counting with Adjacent Deliverables | E13: Double-Counting with Adjacent Deliverables | H13: /Users/ryan/ai-env/projects/chirality-app-test/test/execution-6a/_Estimates/EST_DEL-02-07_2026-02-18_1600/Risk_Register.md
A14: DEL-02-07::RISK-004 | B14: DEL-02-07 | C14: RISK-004 | D14: Seismic Anchorage Requirement | E14: Seismic Anchorage Requirement | H14: /Users/ryan/ai-env/projects/chirality-app-test/test/execution-6a/_Estimates/EST_DEL-02-07_2026-02-18_1600/Risk_Register.md
A15: DEL-03-04::RSK-001 | B15: DEL-03-04 | C15: RSK-001 | D15: Actual utility run lengths significantly differ from assumed 120 m / 40 m due to actual stub locations and building siting | E15: MEDIUM | F15: HIGH | G15: +/-$30,000 to $40,000 | H15: /Users/ryan/ai-env/projects/chirality-app-test/test/execution-6a/_Estimates/EST_DEL-03-04_2026-02-18_2100/Risk_Register.md | I15: HIGH | J15: HIGH
A16: DEL-03-04::RSK-002 | B16: DEL-03-04 | C16: RSK-002 | D16: DEC-004 tie-in allowance ($35,000) is insufficient to cover actual tie-in execution costs | E16: MEDIUM | F16: MEDIUM | G16: +$15,000 (if actual = $50,000 high end of UU-12 range) | H16: /Users/ryan/ai-env/projects/chirality-app-test/test/execution-6a/_Estimates/EST_DEL-03-04_2026-02-18_2100/Risk_Register.md | I16: MEDIUM | J16: MEDIUM
A17: DEL-03-04::RSK-003 | B17: DEL-03-04 | C17: RSK-003 | D17: Utility connection fees exceed recommended parametric values | E17: MEDIUM | F17: LOW | G17: +$10,000 to $20,000 | H17: /Users/ryan/ai-env/projects/chirality-app-test/test/execution-6a/_Estimates/EST_DEL-03-04_2026-02-18_2100/Risk_Register.md | I17: LOW | J17: LOW
A18: DEL-03-04::RSK-004 | B18: DEL-03-04 | C18: RSK-004 | D18: Cold Storage Building requires additional utility services (sanitary, telecom) not currently included | E18: LOW | F18: LOW | G18: +$17,000 (sanitary $13K + telecom $4K) | H18: /Users/ryan/ai-env/projects/chirality-app-test/test/execution-6a/_Estimates/EST_DEL-03-04_2026-02-18_2100/Risk_Register.md | I18: LOW | J18: LOW
A19: DEL-03-04::RSK-005 | B19: DEL-03-04 | C19: RSK-005 | D19: Common trench double-counting (UU-09 cost additive to individual utility rates which include trench) | E19: LOW | F19: LOW | G19: -$10,000 (overstatement) | H19: /Users/ryan/ai-env/projects/chirality-app-test/test/execution-6a/_Estimates/EST_DEL-03-04_2026-02-18_2100/Risk_Register.md | I19: LOW | J19: LOW
A20: DEL-03-04::RSK-006 | B20: DEL-03-04 | C20: RSK-006 | D20: Unknown underground conditions (rock, contamination, high water table) increase trenching costs | E20: LOW | F20: HIGH | G20: +$20,000 to $50,000 | H20: /Users/ryan/ai-env/projects/chirality-app-test/test/execution-6a/_Estimates/EST_DEL-03-04_2026-02-18_2100/Risk_Register.md | I20: HIGH | J20: HIGH
A21: DEL-03-05::RSK-01 | B21: DEL-03-05 | C21: RSK-01 | D21: AEPA conditions of Water Act approval impose additional mitigation requirements (e.g., construction-phase environmental monitoring, post-construction monitoring, additional setback buffers) that require consultant services beyond FP-17 scope. | E21: MEDIUM | F21: MEDIUM ($10,000-$30,000 additional) | G21: Confirm AEPA application status early in design phase; request pre-consultation with AEPA to scope conditions. | H21: /Users/ryan/ai-env/projects/chirality-app-test/test/execution-6a/_Estimates/EST_DEL-03-05_2026-02-18_2000/Risk_Register.md | I21: MEDIUM | J21: MEDIUM
A22: DEL-03-05::RSK-02 | B22: DEL-03-05 | C22: RSK-02 | D22: 2021 Wetland Assessment and Environmental Assessment have lapsed or are deemed insufficient by AEPA, requiring new assessments. | E22: LOW-MEDIUM | F22: HIGH ($15,000-$30,000+ for new assessments + new ABWRET-A calculation) | G22: Confirm with AEPA whether 2021 reports remain accepted as basis for Water Act application. | H22: /Users/ryan/ai-env/projects/chirality-app-test/test/execution-6a/_Estimates/EST_DEL-03-05_2026-02-18_2000/Risk_Register.md | I22: HIGH | J22: HIGH
A23: DEL-03-05::RSK-03 | B23: DEL-03-05 | C23: RSK-03 | D23: ABWRET-A wetland replacement fee has been recalculated by AEPA at a different amount than the 2021 figure of $10,769.54. | E23: LOW | F23: LOW-MEDIUM (delta could be +/- $2,000-$5,000) | G23: Confirm current ABWRET-A fee with AEPA or through updated assessment. | H23: /Users/ryan/ai-env/projects/chirality-app-test/test/execution-6a/_Estimates/EST_DEL-03-05_2026-02-18_2000/Risk_Register.md | I23: LOW-MEDIUM | J23: LOW-MEDIUM
A24: DEL-03-05::RSK-04 | B24: DEL-03-05 | C24: RSK-04 | D24: Town of Penhold imposes additional flood fringe development conditions requiring additional environmental consultant effort or additional regulatory applications. | E24: LOW-MEDIUM | F24: MEDIUM ($5,000-$15,000) | G24: Engage Town planning department early to confirm flood fringe development requirements. | H24: /Users/ryan/ai-env/projects/chirality-app-test/test/execution-6a/_Estimates/EST_DEL-03-05_2026-02-18_2000/Risk_Register.md | I24: MEDIUM | J24: MEDIUM
A25: DEL-03-05::RSK-05 | B25: DEL-03-05 | C25: RSK-05 | D25: Upstream DEL-03-02 outputs reveal that stormwater discharge points or earthwork volumes near the flood fringe require additional environmental assessment or regulatory coordination. | E25: MEDIUM | F25: MEDIUM ($5,000-$15,000) | G25: Coordinate DEL-03-02 and DEL-03-05 concurrently; flag any flood fringe earthwork volumes for environmental review. | H25: /Users/ryan/ai-env/projects/chirality-app-test/test/execution-6a/_Estimates/EST_DEL-03-05_2026-02-18_2000/Risk_Register.md | I25: MEDIUM | J25: MEDIUM
A26: DEL-04-01::RISK-001 | B26: DEL-04-01 | C26: RISK-001 | D26: Market | E26: PEMB manufacturer pricing may differ from parametric rate ($32/sf) due to steel market volatility, lead times, or regional supply constraints. | F26: MEDIUM | G26: MEDIUM ($24,000 variance at range endpoints: $168K to $210K) | H26: /Users/ryan/ai-env/projects/chirality-app-test/test/execution-6a/_Estimates/EST_DEL-04-01_2026-02-18_1200/Risk_Register.md | I26: MEDIUM | J26: MEDIUM
... A32: DEL-05-02::RSK-004 | B32: DEL-05-02 | C32: RSK-004 | D32: Soil conditions or underground obstructions increase conduit installation cost | E32: LOW | F32: LOW-MEDIUM | G32: Geotech investigation and utility locate as part of site development (DEL-03-02) would inform | H32: /Users/ryan/ai-env/projects/chirality-app-test/test/execution-6a/_Estimates/EST_DEL-05-02_2026-02-18_1600/Risk_Register.md | I32: LOW-MEDIUM | J32: LOW-MEDIUM
A33: DEL-05-03::RSK-001 | B33: DEL-05-03 | C33: RSK-001 | D33: Actual zone count exceeds 10 once DEL-02-01 floor plan is finalized | E33: MEDIUM | F33: Each additional zone adds ~$3,200 (range $2,500-$4,000 per OPT-07). 5 extra zones = ~$16,000 increase. | G33: Re-run estimate with confirmed zone count once DEL-02-01 is available. Carry OPT-07 per-zone rate for sensitivity analysis. | H33: /Users/ryan/ai-env/projects/chirality-app-test/test/execution-6a/_Estimates/EST_DEL-05-03_2026-02-18_1700/Risk_Register.md | I33: MEDIUM
A34: DEL-05-03::RSK-002 | B34: DEL-05-03 | C34: RSK-002 | D34: Parametric pricing significantly understates or overstates actual vendor quote | E34: MEDIUM | F34: OPT-06 range is $35,000-$55,000 (57% spread). Vendor quote could fall outside this range. | G34: Replace with vendor quote as soon as available. Flag to Owner that this is a placeholder estimate. | H34: /Users/ryan/ai-env/projects/chirality-app-test/test/execution-6a/_Estimates/EST_DEL-05-03_2026-02-18_1700/Risk_Register.md | I34: MEDIUM
A35: DEL-05-03::RSK-003 | B35: DEL-05-03 | C35: RSK-003 | D35: Scope boundary disputes at interface with DEL-02-06 (electrical/IT) | E35: LOW | F35: Conduit, low-voltage power, or network costs may be double-counted or missed between deliverables if interface is not clearly coordinated. | G35: Enforce cost ownership rules from brief. Coordinate with DEL-02-06 estimate during aggregation. | H35: /Users/ryan/ai-env/projects/chirality-app-test/test/execution-6a/_Estimates/EST_DEL-05-03_2026-02-18_1700/Risk_Register.md | I35: LOW
A36: DEL-05-03::RSK-004 | B36: DEL-05-03 | C36: RSK-004 | D36: Owner elects both access control (DEL-05-03) and security cameras (DEL-05-04), requiring integration | E36: LOW | F36: Integration costs (shared head-end, software, wiring synergies) are not priced. Could be a cost savings or additional cost depending on system selection. | G36: If both options are elected, re-scope for integration opportunities per Guidance.md. | H36: /Users/ryan/ai-env/projects/chirality-app-test/test/execution-6a/_Estimates/EST_DEL-05-03_2026-02-18_1700/Risk_Register.md | I36: LOW
A37: DEL-05-04::RSK-01 | B37: DEL-05-04 | C37: RSK-01 | D37: Camera count changes significantly once floor plan is finalized (DEL-02-01) | E37: MEDIUM | F37: MEDIUM -- price range for OPT-08 is $40k-$60k; more cameras could exceed range | G37: Re-estimate after DEL-02-01 layout is available; obtain vendor quote with actual camera schedule | H37: /Users/ryan/ai-env/projects/chirality-app-test/test/execution-6a/_Estimates/EST_DEL-05-04_2026-02-18_1800/Risk_Register.md | I37: MEDIUM | J37: MEDIUM
A38: DEL-05-04::RSK-02 | B38: DEL-05-04 | C38: RSK-02 | D38: Scope boundary between camera system (DEL-05-04) and IT infrastructure (DEL-02-06) is unclear for network equipment | E38: MEDIUM | F38: MEDIUM -- potential for double-count or cost gap in network switches/PoE | G38: Coordinate DEL-05-04 and DEL-02-06 estimates; define explicit scope split for network equipment before final pricing | H38: /Users/ryan/ai-env/projects/chirality-app-test/test/execution-6a/_Estimates/EST_DEL-05-04_2026-02-18_1800/Risk_Register.md | I38: MEDIUM | J38: MEDIUM
A39: DEL-05-04::RSK-03 | B39: DEL-05-04 | C39: RSK-03 | D39: Parametric pricing significantly under- or over-estimates actual vendor quote | E39: HIGH | F39: HIGH -- all lines are LOW confidence; OPT-08 range spans $20k ($40k-$60k) | G39: Replace parametric pricing with competitive vendor quotes as soon as possible | H39: /Users/ryan/ai-env/projects/chirality-app-test/test/execution-6a/_Estimates/EST_DEL-05-04_2026-02-18_1800/Risk_Register.md | I39: HIGH | J39: HIGH
A40: DEL-05-04::RSK-04 | B40: DEL-05-04 | C40: RSK-04 | D40: Monitoring service pricing does not reflect actual contract terms (multi-year, escalation, service levels) | E40: MEDIUM | F40: LOW -- annual cost is $5,400; variance within $3,600-$7,200 range | G40: Obtain monitoring service proposals; confirm contract structure (annual vs multi-year) | H40: /Users/ryan/ai-env/projects/chirality-app-test/test/execution-6a/_Estimates/EST_DEL-05-04_2026-02-18_1800/Risk_Register.md | I40: LOW | J40: LOW
A41: DEL-05-04::RSK-05 | B41: DEL-05-04 | C41: RSK-05 | D41: Integration with access control (DEL-05-03) adds unpriced cost if both options are elected | E41: LOW | F41: LOW -- integration cost likely modest relative to system total | G41: If both options are elected, add integration line item in a future estimate revision | H41: /Users/ryan/ai-env/projects/chirality-app-test/test/execution-6a/_Estimates/EST_DEL-05-04_2026-02-18_1800/Risk_Register.md | I41: LOW | J41: LOW

Sheet BOE_Collection
A1: Basis of Estimate Collection (Project Level)
